Workbook

Sheet 2025 结构设计订单 
A1: 2025财年结构设计订单管理
A2: 序号 | B2: 订单号 | C2: 容量 MVA | D2: 电压 Kv | E2: 客户 | F2: 国内/出口 | G2: 台数 | H2: 项目负责人 一次 | I2: 项目负责人 二次 | J2: 一次图纸 提交日期 | K2: 一次图纸 确认日期 | L2: 设计工具 | M2: 二次图纸 提交日期 | N2: 二次图纸 确认日期 | O2: 是否分体 大架子 | P2: 是否试验套管 | Q2: 试验套管型号及 数量，目前套管能具备几台同时试验的条件? | R2: 开关数量 | S2: 焊接箱沿 | U2: 问题汇总
A3: 69 | B3: 812645~812654 | C3: 334 | D3: 500 | E3: NGCP | F3: 出口 | G3: 7 | H3: 郭运波 | I3: 司林杰 | J3: 44755 | K3: 44893 | L3: 2D | M3: 45487 | N3: 44956 | T3: copy design 812825
A4: 15 | B4: 812921/2922 | C4: 240 | D4: 220 | E4: 合肥 | F4: 国内 | G4: 2 | H4: 戚彬 | I4: 李世升 | J4: 45323 | K4: 45436 | L4: 2D | M4: 45436 | T4: copy design 812976
A5: 4 | B5: 812845 | C5: 209 | D5: 150 | E5: Belgium | F5: 出口 | G5: 1 | H5: 陈振东 | I5: 司林杰 | J5: 45345 | K5: 45754 | L5: 2D | M5: 45345 | S5: 是 | T5: 低压套管更换
A6: 70 | B6: 812860~812862 | C6: 550 | D6: 330 | E6: Australia WPC, NREP project | F6: 出口 | G6: 2 | H6: 郭运波 | I6: 王芳 | J6: 45404 | M6: 45412 | O6: 是 | R6: 3 | S6: 是 | T6: copy design 812976
A7: 71 | B7: 812947 | C7: 340 | D7: 330 | E7: Australia Wellington BESS | F7: 出口 | G7: 1 | H7: 郭运波 | I7: 王芳 | J7: 45412 | M7: 45412 | T7: copy design 813063
A8: 72 | B8: 812925 | C8: 400 | D8: 400 | E8: Romania Brazi Vest Substation | F8: 出口 | G8: 1 | H8: 郭运波 | I8: 司林杰 | J8: 45436 | M8: 45436 | T8: Ester oil (Midel 7131)
A9: 73 | B9: 812938~812941 | C9: 160 | D9: 132 | E9: UK GLP Project Olympus | F9: 出口 | G9: 3 | H9: 郭运波 | I9: 司林杰 | J9: 45460 | K9: 45583 | L9: 2D | M9: 45454 | N9: 45583 | O9: 是(错层) | P9: 是 | Q9: 4支40.5kV试验套管 | R9: 3 | T9: Ester oil (Midel 7131) repeat order 822807
A10: 74 | B10: 812952/812953 | C10: 140 | D10: 230 | E10: France_Paris_225kV_Data4 project | F10: 出口 | G10: 2 | H10: 郭运波 | I10: 司林杰 | J10: 45483 | K10: 45510 | L10: 2D | M10: 45483 | N10: 45513 | T10: similar812645
A11: 75 | B11: 812963 | C11: 250 | D11: 400 | E11: RO Cornatelu | F11: 出口 | G11: 1 | H11: 郭运波 | I11: 王芳 | J11: 45485 | L11: 2D | M11: 45488 | T11: TADcurrentversion
A12: 57 | B12: 813046~813048 | C12: 334 | D12: 500 | E12: 四川谭家湾500kV主变增容扩建工程 | F12: 国内 | G12: 3 | H12: 郑瑞阳 | I12: 司林杰 | J12: 45493 | L12: 2D | M12: 45635 | T12: 交货期2026
A13: 16 | B13: 812976 | C13: 160 | D13: 400 | E13: RO PV Butimanu | F13: 出口 | G13: 1 | H13: 戚彬 | I13: 王芳 | J13: 45504 | K13: 45537 | L13: 2D | M13: 45504 | N13: 45545 | T13: 其他备注
A14: 55 | B14: 812855/812856 | C14: 240 | D14: 220 | E14: 杭州祝桥 | F14: 国内 | G14: 2 | H14: 邢晓静 | I14: 王芳 | J14: 45513 | L14: 2D | M14: 45519 | T14: 器身导变812520，但外部套管位置镜像
A15: 77 | B15: 812978 | C15: 250 | D15: 400 | E15: Romania Draganesti Olt | F15: 出口 | G15: 1 | H15: 郭运波 | I15: 王芳 | J15: 45522 | K15: 45538 | L15: 2D | M15: 45523 | N15: 45538 | T15: 器身导变812738
A16: 17 | B16: 812975 | C16: 125 | D16: 400 | E16: RO PV Butimanu | F16: 出口 | G16: 1 | H16: 戚彬 | I16: 王芳 | J16: 45532 | K16: 45545 | L16: 2D | M16: 45528 | N16: 45545 | T16: 器身导变812941，但外部套管位置不同
A17: 18 | B17: 812995 | C17: 290 | D17: 132 | E17: Australia _CPP Williamsdale BESS | G17: 1 | H17: 戚彬 | I17: 王芳 | J17: 45547 | L17: 2D | M17: 45547 | T17: 备用变 现场为广州厂产品
A18: 103 | B18: 812846~812848 | C18: 450 | D18: 400 | E18: Portugal Startcampus EHV SS | F18: 出口 | G18: 3 | H18: 陈振东 | I18: 王芳 | J18: 45555 | L18: 2D | M18: 45559 | R18: 1 | T18: 导变812595
A19: 78 | B19: 813006~813015 | C19: 334 | D19: 500 | E19: Philippines TERRA NE 2 Solar Power Project | F19: 出口 | G19: 10 | H19: 郭运波 | I19: 司林杰 | J19: 45571 | L19: 2D | M19: 202410-10 | S19: 是 | T19: 导变812642， 试验套管完成厂内试验
A20: 79 | B20: 813001~813003 | C20: 150 | D20: 400 | E20: Spain REE reactors | F20: 出口 | G20: 3 | H20: 郭运波 | I20: 司林杰 | J20: 45593 | L20: 3D | M20: 45593 | R20: 无 | T20: 第一台做短路试验
A21: 19 | B21: 813020 | C21: 100 | D21: 400 | E21: Romania Trivalea Mosteni | F21: 出口 | G21: 2 | H21: 戚彬 | I21: 王芳 | J21: 45595 | K21: 45610 | L21: 2D | M21: 45595 | N21: 45610 | T21: 第一台电抗器订单
A22: 2 | B22: 813000 | C22: 170 | D22: 150 | E22: Portugal REN | F22: 出口 | G22: 1 | H22: 张金环 | I22: 司林杰 | J22: 45596 | L22: 2D | M22: 45596 | T22: 错层10米
A23: 115 | B23: 813021/813022 | C23: 200 | D23: 220 | E23: Romania Banca | F23: 出口 | G23: 2 | H23: 高伟廷 | I23: 司林杰 | J23: 45596 | L23: 3D | M23: 45596 | N23: 45632 | T23: 错层10.5米
A24: 119 | B24: 813023 | C24: 200 | D24: 231 | E24: RO Calafat | F24: 出口 | G24: 1 | H24: 高伟廷 | I24: 王芳 | J24: 45606 | L24: 3D | M24: 45606
A25: 3 | B25: 813036 | C25: 310 | D25: 220 | E25: 唐山乐亭月坨岛海上风电 | F25: 国内 | G25: 1 | H25: 张金环 | I25: 王芳 | J25: 45610 | L25: 2D | O25: 是 | P25: 是 | Q25: 占用3支试验套管 | S25: 是 | U25: 错层高度更改 开关压力释放阀选型 海风冷却方式研发 影响设计进度
A26: 20 | B26: 813016 | C26: 100 | D26: 400 | E26: South Africa_ ESKOM | F26: 出口 | G26: 1 | H26: 戚彬 | I26: 司林杰 | J26: 45616 | L26: 2D | M26: 45672
A27: 56 | B27: 812838 | C27: 334 | D27: 500 | E27: 湖南 | F27: 国内 | G27: 1 | H27: 邢晓静 | I27: 王芳 | J27: 45616 | K27: 45628 | L27: 2D | M27: 45616
A28: 104 | B28: 812871~812899 | C28: 83.3 | D28: 400 | E28: Iraq | F28: 出口 | G28: 29 | H28: 陈振东 | I28: 司林杰 | J28: 45616 | L28: 2D | M28: 45616 | R28: 1
A29: 120 | B29: 813017~813019 | C29: 250 | D29: 400 | E29: South Africa_ ESKOM | F29: 出口 | G29: 3 | H29: 高伟廷 | I29: 司林杰 | J29: 45616 | L29: 3D | M29: 45672
A30: 127 | B30: 813035 | C30: 120 | D30: 400 | E30: Mexico Las Glorias | F30: 出口 | G30: 1 | H30: 高伟廷 | I30: 王芳 | J30: 45637 | L30: 3D
A31: 58 | B31: 850652 | C31: 50 | D31: 110 | E31: 杭州万安 | F31: 国内 | G31: 1 | H31: 郑瑞阳 | I31: 司林杰 | J31: 45641 | M31: 45644
A32: 105 | B32: 812996/812997 | C32: 250 | D32: 275 | E32: Indonesia Vantage Data Center KL | F32: 出口 | G32: 2 | H32: 陈振东 | I32: 王芳 | J32: 45641 | L32: 2D | M32: 45648 | P32: 是 | Q32: 占用3支试验套管 | R32: 1
A33: 80 | B33: 813055~813057 | C33: 250 | D33: 220 | E33: Egypt SCATEC | F33: 出口 | G33: 3 | H33: 郭运波 | I33: 王芳 | J33: 45649 | L33: 3D
A34: 58 | B34: 813075-813077 | C34: 334 | D34: 550 | E34: 湖北军山 | F34: 国内 | G34: 3 | H34: 郑瑞阳 | I34: 司林杰 | J34: 45651 | M34: 45709
A35: 31 | B35: 813063 | C35: 220 | D35: 154 | E35: Chile PV Gran Teno | F35: 出口 | G35: 1 | H35: 李咏梅 | I35: 王芳 | J35: 45656
A36: 50 | B36: 813029~813031 | C36: 300 | D36: 410 | E36: Finland_Kristinestad & Anttila SVC PLUS | F36: 出口 | G36: 3 | H36: 李红杰 | I36: 司林杰 | J36: 45670 | L36: 3D | M36: 45668 | U36: ,1，算单评审后offer 更新高压额定电压，电算、结构重新设计 2，客户要求中性点套管耐受3*1N电流，更新套管型号
A37: 106 | B37: 813069/813070 | C37: 300 | D37: 275 | E37: Australia_Supernode Stage 3 Project | F37: 出口 | G37: 2 | H37: 陈振东 | I37: 司林杰 | J37: 45671 | M37: 45672 | P37: 是 | Q37: 占用3支试验套管 | R37: 1 | U37: 器身、引线设计 测绘返修变压器尺寸 设计周期是正常设计2.5倍
A38: 32 | B38: 813005 | C38: 510 | D38: 525 | E38: CA Napanee Simple Cycle | F38: 出口 | G38: 1 | H38: 李咏梅 | I38: 王芳 | J38: 45672 | L38: 3D | U38: 绝缘水平高于500kV，前期投标没有分辨出来，花费大量时间澄清
A39: 81 | B39: 813058/813059 | C39: 175 | D39: 220 | E39: Egypt SCATEC | F39: 出口 | G39: 2 | H39: 郭运波 | I39: 王芳 | J39: 45672 | L39: 3D
A40: 107 | B40: 813062 | C40: 150 | D40: 220 | E40: Peru SUNNY II Solar Plant | F40: 出口 | G40: 1 | H40: 陈振东 | I40: 王芳 | J40: 45672 | M40: 45677 | R40: 1
...

Sheet 2026结构设计订单
A1: 2026财年结构设计订单管理
A2: 序号 | B2: 订单号 | C2: 容量 MVA | D2: 电压 Kv | E2: 客户 | F2: 国内/出口 | G2: 台数 | H2: 项目负责人 一次 | I2: 项目负责人 二次 | J2: 一次图纸 提交日期 | K2: 一次图纸 确认日期 | L2: 设计工具 | M2: 二次图纸 提交日期 | N2: 二次图纸 确认日期 | O2: 是否分体 大架子 | P2: 是否试验套管 | Q2: 试验套管型号及 数量，目前套管能具备几台同时试验的条件? | R2: 开关数量 | S2: 焊接箱沿 | U2: 问题汇总 | V2: 详细设计完成状态
A3: 6 | B3: 812845 | C3: 209 | D3: 150 | E3: Belgium | F3: 出口 | G3: 1 | H3: 陈振东 | I3: 司林杰 | J3: 45345 | K3: 45754 | L3: 2D | M3: 45345 | S3: 是 | T3: 低压套管更换
A4: 110 | B4: 812860~812862 | C4: 550 | D4: 330 | E4: Australia WPC, NREP project | F4: 出口 | G4: 2 | H4: 郭运波 | I4: 王芳 | J4: 45404 | M4: 45412 | O4: 是 | R4: 3 | S4: 是 | T4: copy design 812976
A5: 111 | B5: 812947 | C5: 340 | D5: 330 | E5: Australia Wellington BESS | F5: 出口 | G5: 1 | H5: 郭运波 | I5: 王芳 | J5: 45412 | M5: 45412 | T5: copy design 813063
A6: 112 | B6: 812925 | C6: 400 | D6: 400 | E6: Romania Brazi Vest Substation | F6: 出口 | G6: 1 | H6: 郭运波 | I6: 司林杰 | J6: 45436 | M6: 45436 | T6: Ester oil (Midel 7131)
A7: 113 | B7: 812938~812941 | C7: 160 | D7: 132 | E7: UK GLP Project Olympus | F7: 出口 | G7: 3 | H7: 郭运波 | I7: 司林杰 | J7: 45460 | K7: 45583 | L7: 2D | M7: 45454 | N7: 45583 | O7: 是(错层) | P7: 是 | Q7: 4支40.5kV试验套管 | R7: 3 | T7: Ester oil (Midel 7131) repeat order 822807
A8: 114 | B8: 812952/812953 | C8: 140 | D8: 230 | E8: France_Paris_225kV_Data4 project | F8: 出口 | G8: 2 | H8: 郭运波 | I8: 司林杰 | J8: 45483 | K8: 45510 | L8: 2D | M8: 45483 | N8: 45513 | T8: similar812645
A9: 115 | B9: 812963 | C9: 250 | D9: 400 | E9: RO Cornatelu | F9: 出口 | G9: 1 | H9: 郭运波 | I9: 王芳 | J9: 45485 | L9: 2D | M9: 45488 | T9: TADcurrentversion
A10: 96 | B10: 813046~813048 | C10: 334 | D10: 500 | E10: 四川谭家湾500kV主变增容扩建工程 | F10: 国内 | G10: 3 | H10: 郑瑞阳 | I10: 司林杰 | J10: 45493 | L10: 2D | M10: 45504 | T10: 交货期2026
A11: 21 | B11: 812976 | C11: 160 | D11: 400 | E11: RO PV Butimanu | F11: 出口 | G11: 1 | H11: 戚彬 | I11: 王芳 | J11: 45504 | K11: 45537 | L11: 2D | M11: 45519 | N11: 45545 | T11: 其他备注
A12: 92 | B12: 812855/812856 | C12: 240 | D12: 220 | E12: 杭州祝桥 | F12: 国内 | G12: 2 | H12: 邢晓静 | I12: 王芳 | J12: 45513 | L12: 2D | M12: 45523 | T12: 器身导变812520，但外部套管位置镜像
A13: 116 | B13: 812978 | C13: 250 | D13: 400 | E13: Romania Draganesti Olt | F13: 出口 | G13: 1 | H13: 郭运波 | I13: 王芳 | J13: 45522 | K13: 45538 | L13: 2D | M13: 45528 | N13: 45538 | T13: 器身导变812738
A14: 23 | B14: 812975 | C14: 125 | D14: 400 | E14: RO PV Butimanu | F14: 出口 | G14: 1 | H14: 戚彬 | I14: 王芳 | J14: 45532 | K14: 45545 | L14: 2D | M14: 45547 | N14: 45545 | T14: 器身导变812941，但外部套管位置不同
A15: 25 | B15: 812995 | C15: 290 | D15: 132 | E15: Australia _CPP Williamsdale BESS | G15: 1 | H15: 戚彬 | I15: 王芳 | J15: 45547 | L15: 2D | M15: 45559 | T15: 备用变 现场为广州厂产品
A16: 130 | B16: 812846~812848 | C16: 450 | D16: 400 | E16: Portugal Startcampus EHV SS | F16: 出口 | G16: 3 | H16: 陈振东 | I16: 王芳 | J16: 45555 | L16: 3D | M16: 45593 | R16: 1 | T16: 导变812595
A17: 117 | B17: 813006~813015 | C17: 334 | D17: 500 | E17: Philippines TERRA NE 2 Solar Power Project | F17: 出口 | G17: 10 | H17: 郭运波 | I17: 司林杰 | J17: 45571 | L17: 2D | M17: 45595 | S17: 是 | T17: 导变812642， 试验套管完成厂内试验
A18: 118 | B18: 813001~813003 | C18: 150 | D18: 400 | E18: Spain REE reactors | F18: 出口 | G18: 3 | H18: 郭运波 | I18: 司林杰 | J18: 45593 | L18: 2D | M18: 45596 | R18: 无 | T18: 第一台做短路试验
A19: 27 | B19: 813020 | C19: 100 | D19: 400 | E19: Romania Trivalea Mosteni | F19: 出口 | G19: 2 | H19: 戚彬 | I19: 王芳 | J19: 45595 | K19: 45610 | L19: 3D | M19: 45596 | N19: 45610 | T19: 第一台电抗器订单
A20: 2 | B20: 813000 | C20: 170 | D20: 150 | E20: Portugal REN | F20: 出口 | G20: 1 | H20: 张金环 | I20: 司林杰 | J20: 45596 | L20: 3D | M20: 45606 | T20: 错层10米
A21: 141 | B21: 813021/813022 | C21: 200 | D21: 220 | E21: Romania Banca | F21: 出口 | G21: 2 | H21: 高伟廷 | I21: 司林杰 | J21: 45596 | M21: 45615 | N21: 45632 | T21: 错层10.5米
A22: 142 | B22: 813023 | C22: 200 | D22: 231 | E22: RO Calafat | F22: 出口 | G22: 1 | H22: 高伟廷 | I22: 王芳 | J22: 45606 | L22: 2D | M22: 45616
A23: 4 | B23: 813036 | C23: 310 | D23: 220 | E23: 唐山乐亭月坨岛海上风电 | F23: 国内 | G23: 1 | H23: 张金环 | I23: 王芳 | J23: 45610 | L23: 2D | M23: 45616 | O23: 是 | P23: 是 | Q23: 占用3支试验套管 | S23: 是 | U23: 错层高度更改 开关压力释放阀选型 海风冷却方式研发 影响设计进度
A24: 29 | B24: 813016 | C24: 100 | D24: 400 | E24: South Africa_ ESKOM | F24: 出口 | G24: 1 | H24: 戚彬 | I24: 司林杰 | J24: 45616 | L24: 2D | M24: 45635
A25: 94 | B25: 812838 | C25: 334 | D25: 500 | E25: 湖南 | F25: 国内 | G25: 1 | H25: 邢晓静 | I25: 王芳 | J25: 45616 | K25: 45628 | M25: 45644
A26: 131 | B26: 812871~812899 | C26: 83.3 | D26: 400 | E26: Iraq | F26: 出口 | G26: 29 | H26: 陈振东 | I26: 司林杰 | J26: 45616 | L26: 2D | M26: 45648 | R26: 1
A27: 143 | B27: 813017~813019 | C27: 250 | D27: 400 | E27: South Africa_ ESKOM | F27: 出口 | G27: 3 | H27: 高伟廷 | I27: 司林杰 | J27: 45616 | L27: 3D | M27: 45668
A28: 148 | B28: 813035 | C28: 120 | D28: 400 | E28: Mexico Las Glorias | F28: 出口 | G28: 1 | H28: 高伟廷 | I28: 王芳 | J28: 45637 | L28: 2D | M28: 45672
A29: 98 | B29: 850652 | C29: 50 | D29: 110 | E29: 杭州万安 | F29: 国内 | G29: 1 | H29: 郑瑞阳 | I29: 司林杰 | J29: 45641 | L29: 3D | M29: 45672
A30: 132 | B30: 812996/812997 | C30: 250 | D30: 275 | E30: Indonesia Vantage Data Center KL | F30: 出口 | G30: 2 | H30: 陈振东 | I30: 王芳 | J30: 45641 | M30: 45672 | P30: 是 | Q30: 占用3支试验套管 | R30: 1
A31: 119 | B31: 813055~813057 | C31: 250 | D31: 220 | E31: Egypt SCATEC | F31: 出口 | G31: 3 | H31: 郭运波 | I31: 王芳 | J31: 45649 | M31: 45677
A32: 97 | B32: 813075-813077 | C32: 334 | D32: 550 | E32: 湖北军山 | F32: 国内 | G32: 3 | H32: 郑瑞阳 | I32: 司林杰 | J32: 45651 | L32: 3D | M32: 45678
A33: 45 | B33: 813063 | C33: 220 | D33: 154 | E33: Chile PV Gran Teno | F33: 出口 | G33: 1 | H33: 李咏梅 | I33: 王芳 | J33: 45656 | M33: 45680
A34: 79 | B34: 813029~813031 | C34: 300 | D34: 410 | E34: Finland_Kristinestad & Anttila SVC PLUS | F34: 出口 | G34: 3 | H34: 李红杰 | I34: 司林杰 | J34: 45670 | M34: 45681 | U34: ,1，算单评审后offer 更新高压额定电压，电算、结构重新设计 2，客户要求中性点套管耐受3*1N电流，更新套管型号
A35: 133 | B35: 813069/813070 | C35: 300 | D35: 275 | E35: Australia_Supernode Stage 3 Project | F35: 出口 | G35: 2 | H35: 陈振东 | I35: 司林杰 | J35: 45671 | M35: 45709 | P35: 是 | Q35: 占用3支试验套管 | R35: 1 | U35: 器身、引线设计 测绘返修变压器尺寸 设计周期是正常设计2.5倍
A36: 47 | B36: 813005 | C36: 510 | D36: 525 | E36: CA Napanee Simple Cycle | F36: 出口 | G36: 1 | H36: 李咏梅 | I36: 王芳 | J36: 45672 | M36: 45712 | U36: 绝缘水平高于500kV，前期投标没有分辨出来，花费大量时间澄清
A37: 120 | B37: 813058/813059 | C37: 175 | D37: 220 | E37: Egypt SCATEC | F37: 出口 | G37: 2 | H37: 郭运波 | I37: 王芳 | J37: 45672 | M37: 45721
A38: 134 | B38: 813062 | C38: 150 | D38: 220 | E38: Peru SUNNY II Solar Plant | F38: 出口 | G38: 1 | H38: 陈振东 | I38: 王芳 | J38: 45672 | M38: 45742 | R38: 1
A39: 7 | B39: 813079-813080 | C39: 300 | D39: 220 | E39: 广州紫研老挝Laos | F39: 出口 | G39: 2 | H39: 张金环 | I39: 司林杰 | J39: 45680 | K39: 45689 | M39: 45756
A40: 104 | B40: 813071 | C40: 180 | D40: 220 | E40: 浙江尖山新区 | F40: 国内 | G40: 1 | H40: 郑瑞阳 | I40: 董立乔 | J40: 45680 | M40: 45756 | N40: 45741
...

Sheet 问题汇总
B3: 内容 | C3: 2 | D3: 输入日期 | E3: 订单号 | F3: 问题描述 | G3: 行动计划 | H3: 一次技术负责人 | I3: 二次技术负责人 | J3: 负责人 | K3: 要求完成日期 | L3: 实际完成日期 | M3: 完成状态 | N3: 额外时间
C4: 13
B5: 影响设计 | C5: 1 | D5: 45976 | E5: 812645 | F5: MR开关实物与提供的图纸不符 | G5: 1-调整引线设计 2 | M5: close | N5: 8
B6: 影响设计 | C6: 14 | D6: 45977 | E6: 813016 | F6: 油位计带槽，与供货商提供的图纸不一致 | G6: 1-将油枕侧法兰改为不带槽 | M6: close | N6: 2
B7: 影响设计 | C7: 4 | D7: 45978 | E7: 850620 | F7: 测绘尺寸不对，窗高测成了上下夹件间距 | G7: 重新设计 | M7: close | N7: 67.5
B8: 影响设计 | C8: 5 | D8: 45978 | E8: 813069 | F8: 客户要求更改相序，仍未最终确定，一旦更改，结构将重新设计 | M8: close
B9: 影响设计 | C9: 6 | D9: 45978 | E9: 813175 | F9: 电算将调压线圈线规设计错误，讨论结构更改内容后不再更改 | M9: close | N9: 8
B10: 影响设计 | C10: 7 | D10: 45978 | E10: 813115 | F10: Hitach套管到不了货，需要临时套管做试验 | M10: close
B11: 影响设计 | C11: 8 | D11: 45979 | E11: 813016 | F11: 智达套管无法按时到货，讨论临时套管试验方案 | M11: close | N11: 6
B12: 影响设计 | C12: 9 | D12: 45980 | E12: 812855 | F12: MR提供的开关瓦斯继电器与自己的图纸不符，设计出处理方案 | M12: close | N12: 3
B13: 影响设计 | C13: 10 | D13: 45981 | E13: 812178/813215 | F13: 图纸未确认，投产后客户提出更改控制柜位置，油箱、箱盖更改 | M13: close | N13: 8
B14: 影响设计 | C14: 11 | D14: 45980 | E14: 813205-813207 | F14: copy design EPC对附件的每份图纸都给出很多意见 需要逐条回复 | G14: 客户确认一次、二次图纸 | H14: 李咏梅 | I14: 司林杰 | J14: 周坤 | K14: 12月15号 | M14: close | N14: 8
B15: 订单相关 | C15: 15 | D15: 45982 | E15: 813081 | F15: 2025-4月份第一次提图，至今未确认 客户返回开关意见(2025-12-1) | G15: 客户确认一次、二次图纸 有取消订单的可能 PM 组织MR及客户开会沟通-已沟通 PM 可以展开详细设计 PM 将项目更改事项对应更新checklist | H15: 李咏梅 | I15: 司林杰 | J15: 周骞 | K15: 45989 | L15: 45992 | M15: close
B16: 订单相关 | C16: 16 | D16: 45982 | E16: 813037 | F16: 客户提供新的抗震要求，HSP原设计图纸不满足客户新要求 | G16: 1-PM尝试说服客户接受原HSP套管 2-HSP提供满足要求的套管图纸、套管材质及抗震报告(影响成本及交期)-2025-12-09 项目经理确认HSP套管满足抗震要求，此项关闭 3- PM考虑是否可以换成沈阳传奇的套管 4-客户找HSP讨论，公司可以先用现套管做试验 | H16: 郭运波 | I16: NA | J16: 黄丹慧 | K16: 45989 | L16: 46000 | M16: close | N16: 8
B17: 订单相关 | C17: 17 | D17: 45980 | E17: 813006/813170/812645 | F17: 智达提供的套管图纸813006，813170，812645尾部均压球尺寸做的不一样，以后能否改成统一的 | G17: 1- 李咏梅负责推进套管尾部结构的标准化 2- 结构设计将标准化套管提交给offer部门 3- 11/28已书面通知智达，标准均压球尺寸 4- 考虑作为标准化套管 | H17: 郭运波 | I17: NA | J17: 李咏梅 | K17: 46022 | L17: 46019 | M17: close | N17: 8
B18: 订单相关 | C18: 18 | D18: 45982 | E18: 8RE061 | F18: 客户有更改绝缘水平至LI 650/275的可能，要尽快确定，以免事后更改 | G18: 11月25号林利润确定是否提高绝缘水平，如果要改，电算重新设计，图纸重新提交 12/1 PM通知不再更改绝缘水平 | H18: 郭运波 | I18: 司林杰 | J18: 林利润 | K18: 45986 | L18: 45992 | M18: close
B19: 订单相关 | C19: 19 | D19: 45985 | E19: 813111/813160 | F19: 1)一次图纸、二次图纸未确认(2025-10-24提供修改版) 2)11/28 客户提出要更改CT参数，未收到具体参数要求（2025-12-5日确认CT 参数） 3) 813111控制柜已开始生产，客户未确认端子 | G19: 客户确认一次、二次图纸 PM-端子部分还需继续澄清，影响端子箱交货期 PM继续催客户确认图纸+1 一二次图纸确认，端子按我司方案 | H19: 李咏梅 | I19: 王芳 | J19: 张勇 | K19: 46006 | L19: 46006 | M19: close | N19: 16
B20: 订单相关 | C20: 20 | D20: 45985 | E20: 813143 | F20: 1)一次图纸、二次图纸未确认(11月12号提供修改版，客户答应一周后确认图纸，二次信号没有提供全，设计等待中) 2) 开关图纸需要按客户意见更改，至今未收到MR图纸 | G20: 1-客户确认一次图纸 2-二次信号全部提供(12/1，二次信号已提供) 3-PM答应详设继续(12/1) 4-采购催MR提交图纸 5-PM 催客户确认二次图纸, 6.施乐百风机数量及噪音问题，噪音只有1dBA的裕度，需提前通知试验室注意。 7.开关MR通知要把电动机构改为ED,进一步落实。2026-1-3日确认更改为ED 8.MR 提供更改ED 后的图纸 采购+1W+2W, 2026-01-19 提供图纸 9.2026-01-19 重新更新一次二次图纸，发客户确认 10,.2026-02-02 客户已确认 | H20: 李咏梅 | I20: 王芳 | J20: 庄琰 | K20: 45980 | M20: close
B21: 订单相关 | C21: 21 | D21: 45985 | E21: 813115 | F21: Hitach套管到不了货，需要临时套管做试验 | G21: 1- 是否只有高压和中压套管无法到货？ 低压和中性点的COMEN套管能按时到货。 2-几台变压器需要做试验布置？ 3-库存套管列表里的是否都能选用？ 4-由于原高压引线用的ABB套管自带均压球， 与试验套管尾部不同，所以需要重做一套高压引线 目前看满足交期，后续需要跟踪 | H21: 郭运波 | I21: NA | J21: 史乾坤 | K21: 45995 | M21: close
B22: 订单相关 | C22: 22 | D22: 45985 | E22: 822947 | F22: 算单更新，更新订单号。重新检查并进行设计 | G22: 原812947订单文件是否重新出具？ 可以在CSL822947中引用C812947-14BU02 | H22: 郭运波 | I22: NA | J22: 黄丹慧 | K22: 45994 | L22: 45994 | M22: close
B23: 订单相关 | C23: 23 | D23: 45992 | E23: 813197 | F23: 1) ABB 气体继电器资料不全 2) Weschler advantage 在线监测资料不全 | G23: 催供货商提供设计所需资料 | H23: NA | I23: 王芳 | J23: 徐海梅 | K23: 45996 | L23: 45996 | M23: close
B24: 订单相关 | C24: 24 | D24: 45992 | E24: 813245 | F24: 1)一次图纸提交后，根据客户要求改版两次，至今未确认 2)二次图纸11/28提交 3）MR未提交开关图纸 4)设计院额外要求提供计算机电缆, | G24: 1- PM催客户尽快确认图纸+1 2-采购催MR尽快提交开关二次图纸-close 3,PM确认要什么型号电缆 4.一次已经确认，二次稍有意见，可以往下进行 2026-04-13 设计院提落地供控制柜位置，核实发货电缆长度，2026-05-11已确认 | H24: 郑瑞阳 | I24: 董立乔 | J24: 周坤 | K24: 46006 | L24: 46006 | M24: Close
B25: 订单相关 | C25: 25 | D25: 45992 | E25: 813242 | F25: 1) 一次、二次图纸未确认(10月17号提交) | G25: 1-PM催客户确认图纸 | H25: 戚彬 | I25: 王芳 | J25: 庄琰 | K25: 46006 | L25: 46006 | M25: close
B26: 订单相关 | C26: 26 | D26: 45992 | E26: 813133/813153 | F26: 1) 一次、二次图纸未确认(6月15号提交) | G26: 1-PM催客户确认图纸(PM答应不用等客户确认) | H26: 李咏梅 | I26: 王芳 | J26: 林利润 | K26: 45992 | L26: 45992 | M26: close
B27: 订单相关 | C27: 27 | D27: 45992 | E27: 813025 | F27: 1) 一次二次图纸未确认(8月份提图) | G27: 1-PM 通知一次图纸确认，但是客户后续增加SEGRI 充氮灭火 2-PM通知确认二次图纸 2025-12-09确认 | H27: 李咏梅 | I27: 司林杰 | J27: 周骞 | K27: 46006 | L27: 46006 | M27: close
B28: 订单相关 | C28: 28 | D28: 45992 | E28: 813028 | F28: 1) 一次二次图纸未确认(8月份提图) | G28: 1-PM 通知一次图纸确认，但是客户后续增加SEGRI 充氮灭火 2-PM催客户确认二次图纸 2025-12-09确认 | H28: 李咏梅 | I28: 司林杰 | J28: 周骞 | K28: 46006 | L28: 46006 | M28: close
B29: 订单相关 | C29: 29 | D29: 45992 | E29: 813201 | F29: 1) 一次二次图纸未确认(9月份提图) | G29: 1-PM 确认图纸 | H29: 李红杰 | I29: 王芳 | J29: 黄丹慧 | K29: 46006 | L29: 46006 | M29: close
B30: 订单相关 | C30: 30 | D30: 45999 | E30: 813060 | F30: MR开关二次2025-10-28日图纸意见 | G30: 1, 采购催MR尽快回复开关二次图纸意见及图纸更新 | H30: 张金环 | I30: 司林杰 | J30: 徐海梅 | K30: 46006 | L30: 46006 | M30: close
B31: 订单相关 | C31: 31 | D31: 45999 | E31: 813170 | F31: MR 开关是否提供开关 在线检测平柜 | G31: 1，MR 说服当地客户不提供， 2025-12-15 最新意见：就目前技术 MR在菲律宾寻求新的解决方案 2025-12-22 MR 直接与现场客户确认技术接口，等待MR 报价 2,PM 跟进此问题进程 避免影响项目进行 3. 等待客户意见（是否接受MR的方案） 4, 2026-01-05 客户召集MR开会讨论具体方案 5,2026-01-12 客户确认MR不再负责在线监测远方控制方案，改为DGA （锐开）负责，采购进行询价 并提供图纸 6,2026-01-18 已提供检测图纸，PM发给客户确认 7,2026-01-18 三相电400V改为230V ，影响风机、油泵、开关、二次控制箱，项目经理 确认是否坚持更改，影响太大，PM 2026-1-21号之前答复 8.2026-01-26 PM 确认电源无需更改继续进行 9.2026-01-26 采购催更改MR图纸 | H31: 郭运波 | I31: 司林杰 | J31: 徐海梅/周坤 | K31: 46006 | M31: close
B32: 订单相关 | C32: 32 | D32: 46002 | E32: 813101 | F32: 客户未提供高压电缆终端图纸，影响高压母线箱设计 | G32: PM 催客户提供 电缆终端图纸+1 +2 2026-01-05 PM 沟通升级 通知UAE+1 2026-01-13 客户邮件确认按照标准执行 | H32: 李咏梅 | I32: NA | J32: 张勇 | K32: 46006 | L32: 46035 | M32: close
B33: 订单相关 | C33: 33 | D33: 46006 | E33: 813193 | F33: 1,ABB 套管 变压器测带油罐 2,ABB 国内不生产34.5/13.8kV低压套管 | G33: 1,PM: ABB 套管图纸发给客户确认 2.PM: 72.5kV 代替34.5/13.8kV 套管图纸发给客户确认+1W+2W 3.2026-01-05 ：PM 沟通升级 通知菲律宾 4. 2026-01-12：PM+3W 5. 2026-01-18 套管按照72.5kV下发采购订单，PM需要评估以大代小的风险,PM 2026-01-23之前回复， 6.2026-01-26 PM 继续催促客户确认 7.2026-02-02 PM 继续催促客户确认+1 （采购已经12月份出采购订单） 8,2026-02-09 客户不同意以大代小方案，PM 与客户沟通能否更改套管厂家，PM 联系offer 报价时如何与客户沟通的套管信息 9.2026-03-02 PM需继续催客户同意(计划2026-3-4日与客户开会确认) 10. 2026-03-09 客户口头接受以大代小，等书面正式回复 11. 2026-03-16 客户确认 12.2026-04-13 二次需要确认 仪表要求发订单 2026-04-27二次需要确认 仪表要求发订单+2 2026-05-11确认。 2026-06-12 低压平衡高压中性点共7支套管 客户推翻以大代小，结构设计已经完成，请PM协助尽快确认套管厂家；结构设计重新询图 2026-6-22 PM继续催 2026-06-29 PM 周会信息客户推荐美国ABB 套管，需要PM继续跟进 2026-07-06 PM 周会信息客户推荐美国ABB 套管，需要PM继续跟进 +1 2026-07-13 PM 周会信息客户推荐美国ABB 套管，需要PM继续跟进 +2 2026-07-20 PM 客户确认使用美国ABB 套管，交货期24周？结构设计Review 套管技术资料 尽早下单@老陈；PM review 成本和交货期是否满足要求 2027-07-27 客户确认套管厂家，结构设计下发新的设计订单，详细设更改工作量很大需要八月份重新进入安排进入设计计划 2027-08-03 采购核实美国产ABB 套管 是否影响交期 2027-08-10 PM 林总建议暂时不做详细设计更改，等地美国产ABB 套管交期确认 ;ABB 套管当前报价32周； | H33: 陈振东 | I33: 董立乔 | J33: 周坤 | K33: 46021 | M33: on going
B34: 订单相关 | C34: 39 | D34: 46034 | E34: 812925 | F34: 试验套管数量不够 | G34: 1,2026-01-12:使用4支 252kV 和新库存套管做试验套管， PM确认试验套管是否其他项目使用冲突 2, 2026-01-18 客户不接受试验套管 3,2026-01-26 PM 林与客户再次沟通 4.2026-02-02 PM 与客户沟通 用传奇套管替代HSP供货 5.2026-02-09 客户不同意替代套管电流1250A 代替1600A,采购协助联系传奇能否更改桃套管图纸 6. 2026-03-02 客户不同意传奇套管方案，需要采购继续催HSP交期 7.2026-03-09 确认等原套管做试验，此项目从设计移除。请相关部门关注 | H34: 郭运波 | I34: NA | J34: 周骞 | K34: 1/19/2026 2026-01-31 | L34: 46040 | M34: close
B35: 订单相关 | C35: 35 | D35: 46006 | E35: 813225 | F35: OTI/WTI 大连世友仪表价格超报价，和其光电报价满足技术要求 | G35: 1,PM 说服客户采用和其光电方案，PM已确认和其广电 2, offer 关注客户技术要求 3.,客户接受，方案可行。 | H35: NA | I35: 司林杰 | J35: 邓亮 | K35: 46021 | L35: 46021 | M35: close
B36: 订单相关 | C36: 36 | D36: 46013 | E36: 850620 | F36: 没有开关继电器和压力释放阀接线图，端子箱预留信号，能否现场接线 | G36: 1，PM 确认方案是否可行 2客户接受，方案可行。 | H36: NA | I36: 董立乔 | J36: 庄琰 | K36: 46021 | L36: 46021 | M36: close
B37: 订单相关 | C37: 35 | D37: 46027 | E37: 813095/96 | F37: 试验套管数量不够 | G37: 1,2026-01-05 各部门会议讨论执行方案 2, 2026-01-12 close | H37: 陈振东 | I37: NA | J37: 史乾坤 | K37: 46028 | L37: 46038 | M37: close
B38: 订单相关 | C38: 36 | D38: 46027 | E38: 813025-813028 | F38: 高压套管该电压等级 2026-01-18 确认高压套管550kV 改420kV | G38: 1, 2026-01-05: PM催客户确认方案 2, 2026-01-12: PM催客户确认方案+1w 3, 2026-01-18 采购和 PM 确认 已经采购的550kV套管使用到其他项目 4,2026-01-18 PM 催客户提供420kV套管新的供应商 5,2026-01-18 采购 与传奇沟通是否能够生产该绝缘水平的420kV 套管， 6.2026-01-26 SE 再次与客户沟通原套管（只改电气参数）的可行性 7.2026-02-02 采购协助催传奇改图纸，PM 继续与客户沟通 8.2026-02-09 PM 反馈2026-02-11 客户给答复 9. 2026-03-02：客户已于2026-02-25 确认 | H38: 李咏梅 | I38: NA | J38: 周骞/丁睿 | K38: 46034 | M38: close
B39: 订单相关 | C39: 37 | D39: 46027 | E39: 沙特电抗器 | F39: 沙特电抗器6套提图日期太紧迫 | G39: 1,2026-01-05:PM要求2026-01-15日之前提供6套图纸 2,2026-01-05:TPM 今天按照当前进度提供合理提图日期发给项目经理与客户沟通 3,2026-01-12:最后确认2026-1-31之前提供所有图纸 4,2026-01-12:套管需要提前采购 PM 需执行特殊流程审批 | H39: 郭运波 | I39: 司林杰 | J39: 林林润 | K39: 46034 | L39: 46040 | M39: close
B40: 订单相关 | C40: 38 | D40: 46027 | E40: 813279/813280 | F40: 马来西亚脂油 提图 | G40: 1,2026-01-05：结构设计2026-01-14 提供一次二次图纸 （陈/王芳） | H40: 陈振东 | I40: 王芳 | J40: 周骞 | K40: 46036 | L40: 46040 | M40: close
B41: 订单相关 | C41: 40 | D41: 46034 | E41: 813208 | F41: 一次二次图纸确认 | G41: 2026-01-12： 一次二次图纸确认 2026-01-18：PM 与客户联系年前确认图纸 2026-03-02 客户已于2026-02-12确认图纸 2026-04-13 设计院提落地供控制柜位置，核实发货电缆长度 | H41: 郑瑞阳 | I41: 董立乔 | J41: 庄琰 | K41: 46052 | M41: close
B42: 订单相关 | C42: 41 | D42: 46034 | E42: 813211 | F42: 一次二次图纸确认 | G42: 2026-01-12： 一次二次图纸确认 2026-01-18：低压套管高度更改 ，结构设计更新图纸 发客户确认 2026-01-26 PM 与客户确认 低压套管高度无法降低 2026-02-02 PM 继续联系客户确认 2026-02-09 一次图纸确认，PM 继续催客户确认二次图纸 2026-03-02 客户承诺2026-3-2日给二次确认 2026-03-09 客户已反馈二次意见，03-12更新后提交 2026-03-16 客户已确认二次图纸 2026-04-13 设计院提落地供控制柜位置，核实发货电缆长度 2026-04-27 close | H42: 郑瑞阳 | I42: 董立乔 | J42: 黄丹慧 | K42: 46052 | M42: close
...

Sheet 提图计划
B2: 2026财年结构设计提图计划
B3: 序号 | C3: 订单号 | D3: 容量 MVA | E3: 电压 Kv | F3: 客户 | G3: 国内/出口 | H3: 台数 | I3: 项目负责人 | K3: 一次图纸 | M3: 二次图纸
G4: 国内/出口 | I4: 一次 | J4: 二次 | K4: 提交日期 | L4: 确认日期 | M4: 提交日期 | N4: 确认日期
B5: 1 | C5: ='2025 结构设计订单 '!B52 -> 813090-093 | D5: ='2025 结构设计订单 '!C52 -> 140 | E5: ='2025 结构设计订单 '!D52 -> 230 | F5: ='2025 结构设计订单 '!E52 -> 上海电气埃及 Kom Ombo二期500KV光储EPC项目 | G5: ='2025 结构设计订单 '!F52 -> 出口 | H5: ='2025 结构设计订单 '!G52 -> 4 | I5: =IF((_xlfn.XLOOKUP($C5,'2025 结构设计订单 '!$B:$B,'2025 结构设计订单 '!H:H))=0," ",_xlfn.XLOOKUP($C5,'2025 结构设计订单 '!$B:$B,'2025 结构设计订单 '!H:H)) -> 高伟廷 | J5: =IF((_xlfn.XLOOKUP($C5,'2025 结构设计订单 '!$B:$B,'2025 结构设计订单 '!I:I))=0," ",_xlfn.XLOOKUP($C5,'2025 结构设计订单 '!$B:$B,'2025 结构设计订单 '!I:I)) -> 司林杰 | K5: =IF((_xlfn.XLOOKUP($C5,'2025 结构设计订单 '!$B:$B,'2025 结构设计订单 '!J:J))=0," ",_xlfn.XLOOKUP($C5,'2025 结构设计订单 '!$B:$B,'2025 结构设计订单 '!J:J)) -> 45757 | L5: =IF((_xlfn.XLOOKUP($C5,'2025 结构设计订单 '!$B:$B,'2025 结构设计订单 '!K:K))=0," ",_xlfn.XLOOKUP($C5,'2025 结构设计订单 '!$B:$B,'2025 结构设计订单 '!K:K)) | M5: =IF((_xlfn.XLOOKUP($C5,'2025 结构设计订单 '!$B:$B,'2025 结构设计订单 '!M:M))=0," ",_xlfn.XLOOKUP($C5,'2025 结构设计订单 '!$B:$B,'2025 结构设计订单 '!M:M)) -> 45756 | N5: =IF((_xlfn.XLOOKUP($C5,'2025 结构设计订单 '!$B:$B,'2025 结构设计订单 '!N:N))=0," ",_xlfn.XLOOKUP($C5,'2025 结构设计订单 '!$B:$B,'2025 结构设计订单 '!N:N))
B6: 11 | C6: ='2025 结构设计订单 '!B54 -> 813081-813087 | D6: ='2025 结构设计订单 '!C54 -> 300 | E6: ='2025 结构设计订单 '!D54 -> 420 | F6: ='2025 结构设计订单 '!E54 -> UAE | G6: ='2025 结构设计订单 '!F54 -> 出口 | H6: ='2025 结构设计订单 '!G54 -> 6 | I6: =IF((_xlfn.XLOOKUP($C6,'2025 结构设计订单 '!$B:$B,'2025 结构设计订单 '!H:H))=0," ",_xlfn.XLOOKUP($C6,'2025 结构设计订单 '!$B:$B,'2025 结构设计订单 '!H:H)) -> 李咏梅 | J6: =IF((_xlfn.XLOOKUP($C6,'2025 结构设计订单 '!$B:$B,'2025 结构设计订单 '!I:I))=0," ",_xlfn.XLOOKUP($C6,'2025 结构设计订单 '!$B:$B,'2025 结构设计订单 '!I:I)) -> 司林杰 | K6: =IF((_xlfn.XLOOKUP($C6,'2025 结构设计订单 '!$B:$B,'2025 结构设计订单 '!J:J))=0," ",_xlfn.XLOOKUP($C6,'2025 结构设计订单 '!$B:$B,'2025 结构设计订单 '!J:J)) -> 45762 | L6: =IF((_xlfn.XLOOKUP($C6,'2025 结构设计订单 '!$B:$B,'2025 结构设计订单 '!K:K))=0," ",_xlfn.XLOOKUP($C6,'2025 结构设计订单 '!$B:$B,'2025 结构设计订单 '!K:K)) | M6: =IF((_xlfn.XLOOKUP($C6,'2025 结构设计订单 '!$B:$B,'2025 结构设计订单 '!M:M))=0," ",_xlfn.XLOOKUP($C6,'2025 结构设计订单 '!$B:$B,'2025 结构设计订单 '!M:M)) -> 45762 | N6: =IF((_xlfn.XLOOKUP($C6,'2025 结构设计订单 '!$B:$B,'2025 结构设计订单 '!N:N))=0," ",_xlfn.XLOOKUP($C6,'2025 结构设计订单 '!$B:$B,'2025 结构设计订单 '!N:N))
B7: 13 | C7: ='2025 结构设计订单 '!B55 -> 813037-813045 | D7: ='2025 结构设计订单 '!C55 -> 210 | E7: ='2025 结构设计订单 '!D55 -> 330 | F7: ='2025 结构设计订单 '!E55 -> Australia | G7: ='2025 结构设计订单 '!F55 -> 出口 | H7: ='2025 结构设计订单 '!G55 -> 8 | I7: =IF((_xlfn.XLOOKUP($C7,'2025 结构设计订单 '!$B:$B,'2025 结构设计订单 '!H:H))=0," ",_xlfn.XLOOKUP($C7,'2025 结构设计订单 '!$B:$B,'2025 结构设计订单 '!H:H)) -> 郭运波 | J7: =IF((_xlfn.XLOOKUP($C7,'2025 结构设计订单 '!$B:$B,'2025 结构设计订单 '!I:I))=0," ",_xlfn.XLOOKUP($C7,'2025 结构设计订单 '!$B:$B,'2025 结构设计订单 '!I:I)) -> 王芳 | K7: =IF((_xlfn.XLOOKUP($C7,'2025 结构设计订单 '!$B:$B,'2025 结构设计订单 '!J:J))=0," ",_xlfn.XLOOKUP($C7,'2025 结构设计订单 '!$B:$B,'2025 结构设计订单 '!J:J)) -> 45768 | L7: =IF((_xlfn.XLOOKUP($C7,'2025 结构设计订单 '!$B:$B,'2025 结构设计订单 '!K:K))=0," ",_xlfn.XLOOKUP($C7,'2025 结构设计订单 '!$B:$B,'2025 结构设计订单 '!K:K)) | M7: =IF((_xlfn.XLOOKUP($C7,'2025 结构设计订单 '!$B:$B,'2025 结构设计订单 '!M:M))=0," ",_xlfn.XLOOKUP($C7,'2025 结构设计订单 '!$B:$B,'2025 结构设计订单 '!M:M)) | N7: =IF((_xlfn.XLOOKUP($C7,'2025 结构设计订单 '!$B:$B,'2025 结构设计订单 '!N:N))=0," ",_xlfn.XLOOKUP($C7,'2025 结构设计订单 '!$B:$B,'2025 结构设计订单 '!N:N))
B8: 24 | C8: ='2025 结构设计订单 '!B56 -> 813050~813053 | D8: ='2025 结构设计订单 '!C56 -> 150 | E8: ='2025 结构设计订单 '!D56 -> 400 | F8: ='2025 结构设计订单 '!E56 -> Venezuela project | G8: ='2025 结构设计订单 '!F56 -> 出口 | H8: ='2025 结构设计订单 '!G56 -> 4 | I8: =IF((_xlfn.XLOOKUP($C8,'2025 结构设计订单 '!$B:$B,'2025 结构设计订单 '!H:H))=0," ",_xlfn.XLOOKUP($C8,'2025 结构设计订单 '!$B:$B,'2025 结构设计订单 '!H:H)) -> 陈振东 | J8: =IF((_xlfn.XLOOKUP($C8,'2025 结构设计订单 '!$B:$B,'2025 结构设计订单 '!I:I))=0," ",_xlfn.XLOOKUP($C8,'2025 结构设计订单 '!$B:$B,'2025 结构设计订单 '!I:I)) -> 司林杰 | K8: =IF((_xlfn.XLOOKUP($C8,'2025 结构设计订单 '!$B:$B,'2025 结构设计订单 '!J:J))=0," ",_xlfn.XLOOKUP($C8,'2025 结构设计订单 '!$B:$B,'2025 结构设计订单 '!J:J)) -> 45774 | L8: =IF((_xlfn.XLOOKUP($C8,'2025 结构设计订单 '!$B:$B,'2025 结构设计订单 '!K:K))=0," ",_xlfn.XLOOKUP($C8,'2025 结构设计订单 '!$B:$B,'2025 结构设计订单 '!K:K)) | M8: =IF((_xlfn.XLOOKUP($C8,'2025 结构设计订单 '!$B:$B,'2025 结构设计订单 '!M:M))=0," ",_xlfn.XLOOKUP($C8,'2025 结构设计订单 '!$B:$B,'2025 结构设计订单 '!M:M)) -> 45772 | N8: =IF((_xlfn.XLOOKUP($C8,'2025 结构设计订单 '!$B:$B,'2025 结构设计订单 '!N:N))=0," ",_xlfn.XLOOKUP($C8,'2025 结构设计订单 '!$B:$B,'2025 结构设计订单 '!N:N))
B9: 14 | C9: ='2025 结构设计订单 '!B57 -> 850701 | D9: ='2025 结构设计订单 '!C57 -> 280 | E9: ='2025 结构设计订单 '!D57 -> 400 | F9: ='2025 结构设计订单 '!E57 -> 广西防城港 谭松站 | G9: ='2025 结构设计订单 '!F57 -> 国内 | H9: ='2025 结构设计订单 '!G57 -> 1 | I9: =IF((_xlfn.XLOOKUP($C9,'2025 结构设计订单 '!$B:$B,'2025 结构设计订单 '!H:H))=0," ",_xlfn.XLOOKUP($C9,'2025 结构设计订单 '!$B:$B,'2025 结构设计订单 '!H:H)) -> 李红杰 | J9: =IF((_xlfn.XLOOKUP($C9,'2025 结构设计订单 '!$B:$B,'2025 结构设计订单 '!I:I))=0," ",_xlfn.XLOOKUP($C9,'2025 结构设计订单 '!$B:$B,'2025 结构设计订单 '!I:I)) -> 董立乔 | K9: =IF((_xlfn.XLOOKUP($C9,'2025 结构设计订单 '!$B:$B,'2025 结构设计订单 '!J:J))=0," ",_xlfn.XLOOKUP($C9,'2025 结构设计订单 '!$B:$B,'2025 结构设计订单 '!J:J)) -> 45784 | L9: =IF((_xlfn.XLOOKUP($C9,'2025 结构设计订单 '!$B:$B,'2025 结构设计订单 '!K:K))=0," ",_xlfn.XLOOKUP($C9,'2025 结构设计订单 '!$B:$B,'2025 结构设计订单 '!K:K)) | M9: =IF((_xlfn.XLOOKUP($C9,'2025 结构设计订单 '!$B:$B,'2025 结构设计订单 '!M:M))=0," ",_xlfn.XLOOKUP($C9,'2025 结构设计订单 '!$B:$B,'2025 结构设计订单 '!M:M)) -> 45803 | N9: =IF((_xlfn.XLOOKUP($C9,'2025 结构设计订单 '!$B:$B,'2025 结构设计订单 '!N:N))=0," ",_xlfn.XLOOKUP($C9,'2025 结构设计订单 '!$B:$B,'2025 结构设计订单 '!N:N)) -> 45814
B10: 15 | C10: ='2025 结构设计订单 '!B59 -> 813101-813103 | D10: ='2025 结构设计订单 '!C59 -> 120 | E10: ='2025 结构设计订单 '!D59 -> 132 | F10: ='2025 结构设计订单 '!E59 -> UAE _Transco Haffar | G10: ='2025 结构设计订单 '!F59 -> 出口 | H10: ='2025 结构设计订单 '!G59 -> 3 | I10: =IF((_xlfn.XLOOKUP($C10,'2025 结构设计订单 '!$B:$B,'2025 结构设计订单 '!H:H))=0," ",_xlfn.XLOOKUP($C10,'2025 结构设计订单 '!$B:$B,'2025 结构设计订单 '!H:H)) -> 李咏梅 | J10: =IF((_xlfn.XLOOKUP($C10,'2025 结构设计订单 '!$B:$B,'2025 结构设计订单 '!I:I))=0," ",_xlfn.XLOOKUP($C10,'2025 结构设计订单 '!$B:$B,'2025 结构设计订单 '!I:I)) -> 司林杰 | K10: =IF((_xlfn.XLOOKUP($C10,'2025 结构设计订单 '!$B:$B,'2025 结构设计订单 '!J:J))=0," ",_xlfn.XLOOKUP($C10,'2025 结构设计订单 '!$B:$B,'2025 结构设计订单 '!J:J)) -> 45792 | L10: =IF((_xlfn.XLOOKUP($C10,'2025 结构设计订单 '!$B:$B,'2025 结构设计订单 '!K:K))=0," ",_xlfn.XLOOKUP($C10,'2025 结构设计订单 '!$B:$B,'2025 结构设计订单 '!K:K)) | M10: =IF((_xlfn.XLOOKUP($C10,'2025 结构设计订单 '!$B:$B,'2025 结构设计订单 '!M:M))=0," ",_xlfn.XLOOKUP($C10,'2025 结构设计订单 '!$B:$B,'2025 结构设计订单 '!M:M)) -> 45783 | N10: =IF((_xlfn.XLOOKUP($C10,'2025 结构设计订单 '!$B:$B,'2025 结构设计订单 '!N:N))=0," ",_xlfn.XLOOKUP($C10,'2025 结构设计订单 '!$B:$B,'2025 结构设计订单 '!N:N))
B11: 16 | C11: ='2025 结构设计订单 '!B60 -> 813115-813123 | D11: ='2025 结构设计订单 '!C60 -> 200 | E11: ='2025 结构设计订单 '!D60 -> 400 | F11: ='2025 结构设计订单 '!E60 -> Spain REE | G11: ='2025 结构设计订单 '!F60 -> 出口 | H11: ='2025 结构设计订单 '!G60 -> 9 | I11: =IF((_xlfn.XLOOKUP($C11,'2025 结构设计订单 '!$B:$B,'2025 结构设计订单 '!H:H))=0," ",_xlfn.XLOOKUP($C11,'2025 结构设计订单 '!$B:$B,'2025 结构设计订单 '!H:H)) -> 郭运波 | J11: =IF((_xlfn.XLOOKUP($C11,'2025 结构设计订单 '!$B:$B,'2025 结构设计订单 '!I:I))=0," ",_xlfn.XLOOKUP($C11,'2025 结构设计订单 '!$B:$B,'2025 结构设计订单 '!I:I)) -> 司林杰 | K11: =IF((_xlfn.XLOOKUP($C11,'2025 结构设计订单 '!$B:$B,'2025 结构设计订单 '!J:J))=0," ",_xlfn.XLOOKUP($C11,'2025 结构设计订单 '!$B:$B,'2025 结构设计订单 '!J:J)) -> 45792 | L11: =IF((_xlfn.XLOOKUP($C11,'2025 结构设计订单 '!$B:$B,'2025 结构设计订单 '!K:K))=0," ",_xlfn.XLOOKUP($C11,'2025 结构设计订单 '!$B:$B,'2025 结构设计订单 '!K:K)) | M11: =IF((_xlfn.XLOOKUP($C11,'2025 结构设计订单 '!$B:$B,'2025 结构设计订单 '!M:M))=0," ",_xlfn.XLOOKUP($C11,'2025 结构设计订单 '!$B:$B,'2025 结构设计订单 '!M:M)) -> 45793 | N11: =IF((_xlfn.XLOOKUP($C11,'2025 结构设计订单 '!$B:$B,'2025 结构设计订单 '!N:N))=0," ",_xlfn.XLOOKUP($C11,'2025 结构设计订单 '!$B:$B,'2025 结构设计订单 '!N:N))
B12: 17 | C12: ='2025 结构设计订单 '!B61 -> 813099-813100 | D12: ='2025 结构设计订单 '!C61 -> 160 | E12: ='2025 结构设计订单 '!D61 -> 220 | F12: ='2025 结构设计订单 '!E61 -> 匈牙利Hungary_PV park Sihalom | G12: ='2025 结构设计订单 '!F61 -> 出口 | H12: ='2025 结构设计订单 '!G61 -> 2 | I12: =IF((_xlfn.XLOOKUP($C12,'2025 结构设计订单 '!$B:$B,'2025 结构设计订单 '!H:H))=0," ",_xlfn.XLOOKUP($C12,'2025 结构设计订单 '!$B:$B,'2025 结构设计订单 '!H:H)) -> 陈振东 | J12: =IF((_xlfn.XLOOKUP($C12,'2025 结构设计订单 '!$B:$B,'2025 结构设计订单 '!I:I))=0," ",_xlfn.XLOOKUP($C12,'2025 结构设计订单 '!$B:$B,'2025 结构设计订单 '!I:I)) -> 司林杰 | K12: =IF((_xlfn.XLOOKUP($C12,'2025 结构设计订单 '!$B:$B,'2025 结构设计订单 '!J:J))=0," ",_xlfn.XLOOKUP($C12,'2025 结构设计订单 '!$B:$B,'2025 结构设计订单 '!J:J)) -> 45792 | L12: =IF((_xlfn.XLOOKUP($C12,'2025 结构设计订单 '!$B:$B,'2025 结构设计订单 '!K:K))=0," ",_xlfn.XLOOKUP($C12,'2025 结构设计订单 '!$B:$B,'2025 结构设计订单 '!K:K)) | M12: =IF((_xlfn.XLOOKUP($C12,'2025 结构设计订单 '!$B:$B,'2025 结构设计订单 '!M:M))=0," ",_xlfn.XLOOKUP($C12,'2025 结构设计订单 '!$B:$B,'2025 结构设计订单 '!M:M)) -> 45775 | N12: =IF((_xlfn.XLOOKUP($C12,'2025 结构设计订单 '!$B:$B,'2025 结构设计订单 '!N:N))=0," ",_xlfn.XLOOKUP($C12,'2025 结构设计订单 '!$B:$B,'2025 结构设计订单 '!N:N))
B13: 18 | C13: ='2025 结构设计订单 '!B62 -> 813097-813098 | D13: ='2025 结构设计订单 '!C62 -> 130 | E13: ='2025 结构设计订单 '!D62 -> 220 | F13: ='2025 结构设计订单 '!E62 -> 秘鲁 Peru _Caraveli | G13: ='2025 结构设计订单 '!F62 -> 出口 | H13: ='2025 结构设计订单 '!G62 -> 2 | I13: =IF((_xlfn.XLOOKUP($C13,'2025 结构设计订单 '!$B:$B,'2025 结构设计订单 '!H:H))=0," ",_xlfn.XLOOKUP($C13,'2025 结构设计订单 '!$B:$B,'2025 结构设计订单 '!H:H)) -> 高伟廷 | J13: =IF((_xlfn.XLOOKUP($C13,'2025 结构设计订单 '!$B:$B,'2025 结构设计订单 '!I:I))=0," ",_xlfn.XLOOKUP($C13,'2025 结构设计订单 '!$B:$B,'2025 结构设计订单 '!I:I)) -> 王芳 | K13: =IF((_xlfn.XLOOKUP($C13,'2025 结构设计订单 '!$B:$B,'2025 结构设计订单 '!J:J))=0," ",_xlfn.XLOOKUP($C13,'2025 结构设计订单 '!$B:$B,'2025 结构设计订单 '!J:J)) -> 45792 | L13: =IF((_xlfn.XLOOKUP($C13,'2025 结构设计订单 '!$B:$B,'2025 结构设计订单 '!K:K))=0," ",_xlfn.XLOOKUP($C13,'2025 结构设计订单 '!$B:$B,'2025 结构设计订单 '!K:K)) | M13: =IF((_xlfn.XLOOKUP($C13,'2025 结构设计订单 '!$B:$B,'2025 结构设计订单 '!M:M))=0," ",_xlfn.XLOOKUP($C13,'2025 结构设计订单 '!$B:$B,'2025 结构设计订单 '!M:M)) | N13: =IF((_xlfn.XLOOKUP($C13,'2025 结构设计订单 '!$B:$B,'2025 结构设计订单 '!N:N))=0," ",_xlfn.XLOOKUP($C13,'2025 结构设计订单 '!$B:$B,'2025 结构设计订单 '!N:N))
B14: 19 | C14: ='2025 结构设计订单 '!B63 -> 813161-813162 | D14: ='2025 结构设计订单 '!C63 -> 160 | E14: ='2025 结构设计订单 '!D63 -> 400 | F14: ='2025 结构设计订单 '!E63 -> Romania Saceni | G14: ='2025 结构设计订单 '!F63 -> 出口 | H14: ='2025 结构设计订单 '!G63 -> 2 | I14: =IF((_xlfn.XLOOKUP($C14,'2025 结构设计订单 '!$B:$B,'2025 结构设计订单 '!H:H))=0," ",_xlfn.XLOOKUP($C14,'2025 结构设计订单 '!$B:$B,'2025 结构设计订单 '!H:H)) -> 戚彬 | J14: =IF((_xlfn.XLOOKUP($C14,'2025 结构设计订单 '!$B:$B,'2025 结构设计订单 '!I:I))=0," ",_xlfn.XLOOKUP($C14,'2025 结构设计订单 '!$B:$B,'2025 结构设计订单 '!I:I)) -> 王芳 | K14: =IF((_xlfn.XLOOKUP($C14,'2025 结构设计订单 '!$B:$B,'2025 结构设计订单 '!J:J))=0," ",_xlfn.XLOOKUP($C14,'2025 结构设计订单 '!$B:$B,'2025 结构设计订单 '!J:J)) -> 45798 | L14: =IF((_xlfn.XLOOKUP($C14,'2025 结构设计订单 '!$B:$B,'2025 结构设计订单 '!K:K))=0," ",_xlfn.XLOOKUP($C14,'2025 结构设计订单 '!$B:$B,'2025 结构设计订单 '!K:K)) | M14: =IF((_xlfn.XLOOKUP($C14,'2025 结构设计订单 '!$B:$B,'2025 结构设计订单 '!M:M))=0," ",_xlfn.XLOOKUP($C14,'2025 结构设计订单 '!$B:$B,'2025 结构设计订单 '!M:M)) | N14: =IF((_xlfn.XLOOKUP($C14,'2025 结构设计订单 '!$B:$B,'2025 结构设计订单 '!N:N))=0," ",_xlfn.XLOOKUP($C14,'2025 结构设计订单 '!$B:$B,'2025 结构设计订单 '!N:N))
B15: 2 | C15: ='2025 结构设计订单 '!B64 -> 813155-813156 | D15: ='2025 结构设计订单 '!C64 -> 120MVAr | E15: ='2025 结构设计订单 '!D64 -> 500 | F15: ='2025 结构设计订单 '!E64 -> Vienam_CPMB_Shunt Reactor | G15: ='2025 结构设计订单 '!F64 -> 出口 | H15: ='2025 结构设计订单 '!G64 -> 2 | I15: =IF((_xlfn.XLOOKUP($C15,'2025 结构设计订单 '!$B:$B,'2025 结构设计订单 '!H:H))=0," ",_xlfn.XLOOKUP($C15,'2025 结构设计订单 '!$B:$B,'2025 结构设计订单 '!H:H)) -> 郭运波 | J15: =IF((_xlfn.XLOOKUP($C15,'2025 结构设计订单 '!$B:$B,'2025 结构设计订单 '!I:I))=0," ",_xlfn.XLOOKUP($C15,'2025 结构设计订单 '!$B:$B,'2025 结构设计订单 '!I:I)) -> 董立乔 | K15: =IF((_xlfn.XLOOKUP($C15,'2025 结构设计订单 '!$B:$B,'2025 结构设计订单 '!J:J))=0," ",_xlfn.XLOOKUP($C15,'2025 结构设计订单 '!$B:$B,'2025 结构设计订单 '!J:J)) -> 45810 | L15: =IF((_xlfn.XLOOKUP($C15,'2025 结构设计订单 '!$B:$B,'2025 结构设计订单 '!K:K))=0," ",_xlfn.XLOOKUP($C15,'2025 结构设计订单 '!$B:$B,'2025 结构设计订单 '!K:K)) | M15: =IF((_xlfn.XLOOKUP($C15,'2025 结构设计订单 '!$B:$B,'2025 结构设计订单 '!M:M))=0," ",_xlfn.XLOOKUP($C15,'2025 结构设计订单 '!$B:$B,'2025 结构设计订单 '!M:M)) -> 45821 | N15: =IF((_xlfn.XLOOKUP($C15,'2025 结构设计订单 '!$B:$B,'2025 结构设计订单 '!N:N))=0," ",_xlfn.XLOOKUP($C15,'2025 结构设计订单 '!$B:$B,'2025 结构设计订单 '!N:N))
B16: 3 | C16: ='2025 结构设计订单 '!B65 -> 813175-813177 | D16: ='2025 结构设计订单 '!C65 -> 334 | E16: ='2025 结构设计订单 '!D65 -> 500 | F16: ='2025 结构设计订单 '!E65 -> 山东官亭500千伏变电站 | G16: ='2025 结构设计订单 '!F65 -> 国内 | H16: ='2025 结构设计订单 '!G65 -> 3 | I16: =IF((_xlfn.XLOOKUP($C16,'2025 结构设计订单 '!$B:$B,'2025 结构设计订单 '!H:H))=0," ",_xlfn.XLOOKUP($C16,'2025 结构设计订单 '!$B:$B,'2025 结构设计订单 '!H:H)) -> 郑瑞阳 | J16: =IF((_xlfn.XLOOKUP($C16,'2025 结构设计订单 '!$B:$B,'2025 结构设计订单 '!I:I))=0," ",_xlfn.XLOOKUP($C16,'2025 结构设计订单 '!$B:$B,'2025 结构设计订单 '!I:I)) -> 董立乔 | K16: =IF((_xlfn.XLOOKUP($C16,'2025 结构设计订单 '!$B:$B,'2025 结构设计订单 '!J:J))=0," ",_xlfn.XLOOKUP($C16,'2025 结构设计订单 '!$B:$B,'2025 结构设计订单 '!J:J)) -> 45812 | L16: =IF((_xlfn.XLOOKUP($C16,'2025 结构设计订单 '!$B:$B,'2025 结构设计订单 '!K:K))=0," ",_xlfn.XLOOKUP($C16,'2025 结构设计订单 '!$B:$B,'2025 结构设计订单 '!K:K)) | M16: =IF((_xlfn.XLOOKUP($C16,'2025 结构设计订单 '!$B:$B,'2025 结构设计订单 '!M:M))=0," ",_xlfn.XLOOKUP($C16,'2025 结构设计订单 '!$B:$B,'2025 结构设计订单 '!M:M)) -> 45828 | N16: =IF((_xlfn.XLOOKUP($C16,'2025 结构设计订单 '!$B:$B,'2025 结构设计订单 '!N:N))=0," ",_xlfn.XLOOKUP($C16,'2025 结构设计订单 '!$B:$B,'2025 结构设计订单 '!N:N))
B17: 4 | C17: ='2025 结构设计订单 '!B66 -> 813178-813180 | D17: ='2025 结构设计订单 '!C66 -> 334 | E17: ='2025 结构设计订单 '!D66 -> 500 | F17: ='2025 结构设计订单 '!E66 -> 山东济南500千伏主变增容工程 | G17: ='2025 结构设计订单 '!F66 -> 国内 | H17: ='2025 结构设计订单 '!G66 -> 3 | I17: =IF((_xlfn.XLOOKUP($C17,'2025 结构设计订单 '!$B:$B,'2025 结构设计订单 '!H:H))=0," ",_xlfn.XLOOKUP($C17,'2025 结构设计订单 '!$B:$B,'2025 结构设计订单 '!H:H)) -> 郑瑞阳 | J17: =IF((_xlfn.XLOOKUP($C17,'2025 结构设计订单 '!$B:$B,'2025 结构设计订单 '!I:I))=0," ",_xlfn.XLOOKUP($C17,'2025 结构设计订单 '!$B:$B,'2025 结构设计订单 '!I:I)) -> 董立乔 | K17: =IF((_xlfn.XLOOKUP($C17,'2025 结构设计订单 '!$B:$B,'2025 结构设计订单 '!J:J))=0," ",_xlfn.XLOOKUP($C17,'2025 结构设计订单 '!$B:$B,'2025 结构设计订单 '!J:J)) -> 45814 | L17: =IF((_xlfn.XLOOKUP($C17,'2025 结构设计订单 '!$B:$B,'2025 结构设计订单 '!K:K))=0," ",_xlfn.XLOOKUP($C17,'2025 结构设计订单 '!$B:$B,'2025 结构设计订单 '!K:K)) | M17: =IF((_xlfn.XLOOKUP($C17,'2025 结构设计订单 '!$B:$B,'2025 结构设计订单 '!M:M))=0," ",_xlfn.XLOOKUP($C17,'2025 结构设计订单 '!$B:$B,'2025 结构设计订单 '!M:M)) -> 45841 | N17: =IF((_xlfn.XLOOKUP($C17,'2025 结构设计订单 '!$B:$B,'2025 结构设计订单 '!N:N))=0," ",_xlfn.XLOOKUP($C17,'2025 结构设计订单 '!$B:$B,'2025 结构设计订单 '!N:N))
B18: 10 | C18: ='2025 结构设计订单 '!B67 -> 813133 | D18: ='2025 结构设计订单 '!C67 -> 220 | E18: ='2025 结构设计订单 '!D67 -> 154 | F18: ='2025 结构设计订单 '!E67 -> Chile PV Gran Teno | G18: ='2025 结构设计订单 '!F67 -> 出口 | H18: ='2025 结构设计订单 '!G67 -> 1 | I18: =IF((_xlfn.XLOOKUP($C18,'2025 结构设计订单 '!$B:$B,'2025 结构设计订单 '!H:H))=0," ",_xlfn.XLOOKUP($C18,'2025 结构设计订单 '!$B:$B,'2025 结构设计订单 '!H:H)) -> 李咏梅 | J18: =IF((_xlfn.XLOOKUP($C18,'2025 结构设计订单 '!$B:$B,'2025 结构设计订单 '!I:I))=0," ",_xlfn.XLOOKUP($C18,'2025 结构设计订单 '!$B:$B,'2025 结构设计订单 '!I:I)) -> 王芳 | K18: =IF((_xlfn.XLOOKUP($C18,'2025 结构设计订单 '!$B:$B,'2025 结构设计订单 '!J:J))=0," ",_xlfn.XLOOKUP($C18,'2025 结构设计订单 '!$B:$B,'2025 结构设计订单 '!J:J)) -> 45823 | L18: =IF((_xlfn.XLOOKUP($C18,'2025 结构设计订单 '!$B:$B,'2025 结构设计订单 '!K:K))=0," ",_xlfn.XLOOKUP($C18,'2025 结构设计订单 '!$B:$B,'2025 结构设计订单 '!K:K)) | M18: =IF((_xlfn.XLOOKUP($C18,'2025 结构设计订单 '!$B:$B,'2025 结构设计订单 '!M:M))=0," ",_xlfn.XLOOKUP($C18,'2025 结构设计订单 '!$B:$B,'2025 结构设计订单 '!M:M)) | N18: =IF((_xlfn.XLOOKUP($C18,'2025 结构设计订单 '!$B:$B,'2025 结构设计订单 '!N:N))=0," ",_xlfn.XLOOKUP($C18,'2025 结构设计订单 '!$B:$B,'2025 结构设计订单 '!N:N))
B19: 23 | C19: ='2025 结构设计订单 '!B70 -> 813170 | D19: ='2025 结构设计订单 '!C70 -> 333 | E19: ='2025 结构设计订单 '!D70 -> 500 | F19: ='2025 结构设计订单 '!E70 -> Philippines | G19: ='2025 结构设计订单 '!F70 -> 出口 | H19: ='2025 结构设计订单 '!G70 -> 4 | I19: =IF((_xlfn.XLOOKUP($C19,'2025 结构设计订单 '!$B:$B,'2025 结构设计订单 '!H:H))=0," ",_xlfn.XLOOKUP($C19,'2025 结构设计订单 '!$B:$B,'2025 结构设计订单 '!H:H)) -> 郭运波 | J19: =IF((_xlfn.XLOOKUP($C19,'2025 结构设计订单 '!$B:$B,'2025 结构设计订单 '!I:I))=0," ",_xlfn.XLOOKUP($C19,'2025 结构设计订单 '!$B:$B,'2025 结构设计订单 '!I:I)) -> 司林杰 | K19: =IF((_xlfn.XLOOKUP($C19,'2025 结构设计订单 '!$B:$B,'2025 结构设计订单 '!J:J))=0," ",_xlfn.XLOOKUP($C19,'2025 结构设计订单 '!$B:$B,'2025 结构设计订单 '!J:J)) -> 45828 | L19: =IF((_xlfn.XLOOKUP($C19,'2025 结构设计订单 '!$B:$B,'2025 结构设计订单 '!K:K))=0," ",_xlfn.XLOOKUP($C19,'2025 结构设计订单 '!$B:$B,'2025 结构设计订单 '!K:K)) | M19: =IF((_xlfn.XLOOKUP($C19,'2025 结构设计订单 '!$B:$B,'2025 结构设计订单 '!M:M))=0," ",_xlfn.XLOOKUP($C19,'2025 结构设计订单 '!$B:$B,'2025 结构设计订单 '!M:M)) -> 45834 | N19: =IF((_xlfn.XLOOKUP($C19,'2025 结构设计订单 '!$B:$B,'2025 结构设计订单 '!N:N))=0," ",_xlfn.XLOOKUP($C19,'2025 结构设计订单 '!$B:$B,'2025 结构设计订单 '!N:N))
B20: 12 | C20: ='2025 结构设计订单 '!B71 -> 813159 | D20: ='2025 结构设计订单 '!C71 -> 210 | E20: ='2025 结构设计订单 '!D71 -> 550 | F20: ='2025 结构设计订单 '!E71 -> 沙特SEC电抗器中变 | G20: ='2025 结构设计订单 '!F71 -> 出口 | H20: ='2025 结构设计订单 '!G71 -> 1 | I20: =IF((_xlfn.XLOOKUP($C20,'2025 结构设计订单 '!$B:$B,'2025 结构设计订单 '!H:H))=0," ",_xlfn.XLOOKUP($C20,'2025 结构设计订单 '!$B:$B,'2025 结构设计订单 '!H:H)) -> 李咏梅 | J20: =IF((_xlfn.XLOOKUP($C20,'2025 结构设计订单 '!$B:$B,'2025 结构设计订单 '!I:I))=0," ",_xlfn.XLOOKUP($C20,'2025 结构设计订单 '!$B:$B,'2025 结构设计订单 '!I:I)) -> 董立乔 | K20: =IF((_xlfn.XLOOKUP($C20,'2025 结构设计订单 '!$B:$B,'2025 结构设计订单 '!J:J))=0," ",_xlfn.XLOOKUP($C20,'2025 结构设计订单 '!$B:$B,'2025 结构设计订单 '!J:J)) -> 45833 | L20: =IF((_xlfn.XLOOKUP($C20,'2025 结构设计订单 '!$B:$B,'2025 结构设计订单 '!K:K))=0," ",_xlfn.XLOOKUP($C20,'2025 结构设计订单 '!$B:$B,'2025 结构设计订单 '!K:K)) | M20: =IF((_xlfn.XLOOKUP($C20,'2025 结构设计订单 '!$B:$B,'2025 结构设计订单 '!M:M))=0," ",_xlfn.XLOOKUP($C20,'2025 结构设计订单 '!$B:$B,'2025 结构设计订单 '!M:M)) | N20: =IF((_xlfn.XLOOKUP($C20,'2025 结构设计订单 '!$B:$B,'2025 结构设计订单 '!N:N))=0," ",_xlfn.XLOOKUP($C20,'2025 结构设计订单 '!$B:$B,'2025 结构设计订单 '!N:N))
B21: 30 | C21: ='2025 结构设计订单 '!B72 -> 813153 | D21: ='2025 结构设计订单 '!C72 -> 250 | E21: ='2025 结构设计订单 '!D72 -> 220 | F21: ='2025 结构设计订单 '!E72 -> Chile | G21: ='2025 结构设计订单 '!F72 -> 出口 | H21: ='2025 结构设计订单 '!G72 -> 1 | I21: =IF((_xlfn.XLOOKUP($C21,'2025 结构设计订单 '!$B:$B,'2025 结构设计订单 '!H:H))=0," ",_xlfn.XLOOKUP($C21,'2025 结构设计订单 '!$B:$B,'2025 结构设计订单 '!H:H)) -> 李咏梅 | J21: =IF((_xlfn.XLOOKUP($C21,'2025 结构设计订单 '!$B:$B,'2025 结构设计订单 '!I:I))=0," ",_xlfn.XLOOKUP($C21,'2025 结构设计订单 '!$B:$B,'2025 结构设计订单 '!I:I)) -> 司林杰 | K21: =IF((_xlfn.XLOOKUP($C21,'2025 结构设计订单 '!$B:$B,'2025 结构设计订单 '!J:J))=0," ",_xlfn.XLOOKUP($C21,'2025 结构设计订单 '!$B:$B,'2025 结构设计订单 '!J:J)) -> 45835 | L21: =IF((_xlfn.XLOOKUP($C21,'2025 结构设计订单 '!$B:$B,'2025 结构设计订单 '!K:K))=0," ",_xlfn.XLOOKUP($C21,'2025 结构设计订单 '!$B:$B,'2025 结构设计订单 '!K:K)) | M21: =IF((_xlfn.XLOOKUP($C21,'2025 结构设计订单 '!$B:$B,'2025 结构设计订单 '!M:M))=0," ",_xlfn.XLOOKUP($C21,'2025 结构设计订单 '!$B:$B,'2025 结构设计订单 '!M:M)) -> 45819 | N21: =IF((_xlfn.XLOOKUP($C21,'2025 结构设计订单 '!$B:$B,'2025 结构设计订单 '!N:N))=0," ",_xlfn.XLOOKUP($C21,'2025 结构设计订单 '!$B:$B,'2025 结构设计订单 '!N:N))
B22: 31 | C22: ='2025 结构设计订单 '!B73 -> 813095-813096 | D22: ='2025 结构设计订单 '!C73 -> 450 | E22: ='2025 结构设计订单 '!D73 -> 400 | F22: ='2025 结构设计订单 '!E73 -> 葡萄牙REN | G22: ='2025 结构设计订单 '!F73 -> 出口 | H22: ='2025 结构设计订单 '!G73 -> 3 | I22: =IF((_xlfn.XLOOKUP($C22,'2025 结构设计订单 '!$B:$B,'2025 结构设计订单 '!H:H))=0," ",_xlfn.XLOOKUP($C22,'2025 结构设计订单 '!$B:$B,'2025 结构设计订单 '!H:H)) -> 陈振东 | J22: =IF((_xlfn.XLOOKUP($C22,'2025 结构设计订单 '!$B:$B,'2025 结构设计订单 '!I:I))=0," ",_xlfn.XLOOKUP($C22,'2025 结构设计订单 '!$B:$B,'2025 结构设计订单 '!I:I)) -> 王芳 | K22: =IF((_xlfn.XLOOKUP($C22,'2025 结构设计订单 '!$B:$B,'2025 结构设计订单 '!J:J))=0," ",_xlfn.XLOOKUP($C22,'2025 结构设计订单 '!$B:$B,'2025 结构设计订单 '!J:J)) -> 45838 | L22: =IF((_xlfn.XLOOKUP($C22,'2025 结构设计订单 '!$B:$B,'2025 结构设计订单 '!K:K))=0," ",_xlfn.XLOOKUP($C22,'2025 结构设计订单 '!$B:$B,'2025 结构设计订单 '!K:K)) | M22: =IF((_xlfn.XLOOKUP($C22,'2025 结构设计订单 '!$B:$B,'2025 结构设计订单 '!M:M))=0," ",_xlfn.XLOOKUP($C22,'2025 结构设计订单 '!$B:$B,'2025 结构设计订单 '!M:M)) -> 45838 | N22: =IF((_xlfn.XLOOKUP($C22,'2025 结构设计订单 '!$B:$B,'2025 结构设计订单 '!N:N))=0," ",_xlfn.XLOOKUP($C22,'2025 结构设计订单 '!$B:$B,'2025 结构设计订单 '!N:N))
B23: 22 | C23: ='2025 结构设计订单 '!B74 -> 813028 | D23: ='2025 结构设计订单 '!C74 -> 165 | E23: ='2025 结构设计订单 '!D74 -> 330 | F23: ='2025 结构设计订单 '!E74 -> Nigeria Brownfield | G23: ='2025 结构设计订单 '!F74 -> 出口 | H23: ='2025 结构设计订单 '!G74 -> 1 | I23: =IF((_xlfn.XLOOKUP($C23,'2025 结构设计订单 '!$B:$B,'2025 结构设计订单 '!H:H))=0," ",_xlfn.XLOOKUP($C23,'2025 结构设计订单 '!$B:$B,'2025 结构设计订单 '!H:H)) -> 李红杰 | J23: =IF((_xlfn.XLOOKUP($C23,'2025 结构设计订单 '!$B:$B,'2025 结构设计订单 '!I:I))=0," ",_xlfn.XLOOKUP($C23,'2025 结构设计订单 '!$B:$B,'2025 结构设计订单 '!I:I)) -> 司林杰 | K23: =IF((_xlfn.XLOOKUP($C23,'2025 结构设计订单 '!$B:$B,'2025 结构设计订单 '!J:J))=0," ",_xlfn.XLOOKUP($C23,'2025 结构设计订单 '!$B:$B,'2025 结构设计订单 '!J:J)) -> 45842 | L23: =IF((_xlfn.XLOOKUP($C23,'2025 结构设计订单 '!$B:$B,'2025 结构设计订单 '!K:K))=0," ",_xlfn.XLOOKUP($C23,'2025 结构设计订单 '!$B:$B,'2025 结构设计订单 '!K:K)) | M23: =IF((_xlfn.XLOOKUP($C23,'2025 结构设计订单 '!$B:$B,'2025 结构设计订单 '!M:M))=0," ",_xlfn.XLOOKUP($C23,'2025 结构设计订单 '!$B:$B,'2025 结构设计订单 '!M:M)) -> 45842 | N23: =IF((_xlfn.XLOOKUP($C23,'2025 结构设计订单 '!$B:$B,'2025 结构设计订单 '!N:N))=0," ",_xlfn.XLOOKUP($C23,'2025 结构设计订单 '!$B:$B,'2025 结构设计订单 '!N:N))
B24: 32 | C24: ='2025 结构设计订单 '!B74 -> 813028 | D24: ='2025 结构设计订单 '!C74 -> 165 | E24: ='2025 结构设计订单 '!D74 -> 330 | F24: ='2025 结构设计订单 '!E74 -> Nigeria Brownfield | G24: ='2025 结构设计订单 '!F74 -> 出口 | H24: ='2025 结构设计订单 '!G74 -> 1 | I24: =IF((_xlfn.XLOOKUP($C24,'2025 结构设计订单 '!$B:$B,'2025 结构设计订单 '!H:H))=0," ",_xlfn.XLOOKUP($C24,'2025 结构设计订单 '!$B:$B,'2025 结构设计订单 '!H:H)) -> 李红杰 | J24: =IF((_xlfn.XLOOKUP($C24,'2025 结构设计订单 '!$B:$B,'2025 结构设计订单 '!I:I))=0," ",_xlfn.XLOOKUP($C24,'2025 结构设计订单 '!$B:$B,'2025 结构设计订单 '!I:I)) -> 司林杰 | K24: =IF((_xlfn.XLOOKUP($C24,'2025 结构设计订单 '!$B:$B,'2025 结构设计订单 '!J:J))=0," ",_xlfn.XLOOKUP($C24,'2025 结构设计订单 '!$B:$B,'2025 结构设计订单 '!J:J)) -> 45842 | L24: =IF((_xlfn.XLOOKUP($C24,'2025 结构设计订单 '!$B:$B,'2025 结构设计订单 '!K:K))=0," ",_xlfn.XLOOKUP($C24,'2025 结构设计订单 '!$B:$B,'2025 结构设计订单 '!K:K)) | M24: =IF((_xlfn.XLOOKUP($C24,'2025 结构设计订单 '!$B:$B,'2025 结构设计订单 '!M:M))=0," ",_xlfn.XLOOKUP($C24,'2025 结构设计订单 '!$B:$B,'2025 结构设计订单 '!M:M)) -> 45842 | N24: =IF((_xlfn.XLOOKUP($C24,'2025 结构设计订单 '!$B:$B,'2025 结构设计订单 '!N:N))=0," ",_xlfn.XLOOKUP($C24,'2025 结构设计订单 '!$B:$B,'2025 结构设计订单 '!N:N))
B25: 25 | C25: ='2025 结构设计订单 '!B75 -> 813191-813193 | D25: ='2025 结构设计订单 '!C75 -> 30MVAr | E25: ='2025 结构设计订单 '!D75 -> 230 | F25: ='2025 结构设计订单 '!E75 -> 霞浦B区陆上集控站 | G25: ='2025 结构设计订单 '!F75 -> 国内 | H25: ='2025 结构设计订单 '!G75 -> 2 | I25: =IF((_xlfn.XLOOKUP($C25,'2025 结构设计订单 '!$B:$B,'2025 结构设计订单 '!H:H))=0," ",_xlfn.XLOOKUP($C25,'2025 结构设计订单 '!$B:$B,'2025 结构设计订单 '!H:H)) -> 戚彬 | J25: =IF((_xlfn.XLOOKUP($C25,'2025 结构设计订单 '!$B:$B,'2025 结构设计订单 '!I:I))=0," ",_xlfn.XLOOKUP($C25,'2025 结构设计订单 '!$B:$B,'2025 结构设计订单 '!I:I)) -> 董立乔 | K25: =IF((_xlfn.XLOOKUP($C25,'2025 结构设计订单 '!$B:$B,'2025 结构设计订单 '!J:J))=0," ",_xlfn.XLOOKUP($C25,'2025 结构设计订单 '!$B:$B,'2025 结构设计订单 '!J:J)) -> 45848 | L25: =IF((_xlfn.XLOOKUP($C25,'2025 结构设计订单 '!$B:$B,'2025 结构设计订单 '!K:K))=0," ",_xlfn.XLOOKUP($C25,'2025 结构设计订单 '!$B:$B,'2025 结构设计订单 '!K:K)) | M25: =IF((_xlfn.XLOOKUP($C25,'2025 结构设计订单 '!$B:$B,'2025 结构设计订单 '!M:M))=0," ",_xlfn.XLOOKUP($C25,'2025 结构设计订单 '!$B:$B,'2025 结构设计订单 '!M:M)) -> 45848 | N25: =IF((_xlfn.XLOOKUP($C25,'2025 结构设计订单 '!$B:$B,'2025 结构设计订单 '!N:N))=0," ",_xlfn.XLOOKUP($C25,'2025 结构设计订单 '!$B:$B,'2025 结构设计订单 '!N:N))
B26: 27 | C26: ='2025 结构设计订单 '!B76 -> 813111~813113 | D26: ='2025 结构设计订单 '!C76 -> 280 | E26: ='2025 结构设计订单 '!D76 -> 400 | F26: ='2025 结构设计订单 '!E76 -> UK_Statera Energy Framework | G26: ='2025 结构设计订单 '!F76 -> 出口 | H26: ='2025 结构设计订单 '!G76 -> 3 | I26: =IF((_xlfn.XLOOKUP($C26,'2025 结构设计订单 '!$B:$B,'2025 结构设计订单 '!H:H))=0," ",_xlfn.XLOOKUP($C26,'2025 结构设计订单 '!$B:$B,'2025 结构设计订单 '!H:H)) -> 李咏梅 | J26: =IF((_xlfn.XLOOKUP($C26,'2025 结构设计订单 '!$B:$B,'2025 结构设计订单 '!I:I))=0," ",_xlfn.XLOOKUP($C26,'2025 结构设计订单 '!$B:$B,'2025 结构设计订单 '!I:I)) -> 王芳 | K26: =IF((_xlfn.XLOOKUP($C26,'2025 结构设计订单 '!$B:$B,'2025 结构设计订单 '!J:J))=0," ",_xlfn.XLOOKUP($C26,'2025 结构设计订单 '!$B:$B,'2025 结构设计订单 '!J:J)) -> 45848 | L26: =IF((_xlfn.XLOOKUP($C26,'2025 结构设计订单 '!$B:$B,'2025 结构设计订单 '!K:K))=0," ",_xlfn.XLOOKUP($C26,'2025 结构设计订单 '!$B:$B,'2025 结构设计订单 '!K:K)) | M26: =IF((_xlfn.XLOOKUP($C26,'2025 结构设计订单 '!$B:$B,'2025 结构设计订单 '!M:M))=0," ",_xlfn.XLOOKUP($C26,'2025 结构设计订单 '!$B:$B,'2025 结构设计订单 '!M:M)) -> 45849 | N26: =IF((_xlfn.XLOOKUP($C26,'2025 结构设计订单 '!$B:$B,'2025 结构设计订单 '!N:N))=0," ",_xlfn.XLOOKUP($C26,'2025 结构设计订单 '!$B:$B,'2025 结构设计订单 '!N:N))
B27: 28 | C27: ='2025 结构设计订单 '!B77 -> 813072-813073 | D27: ='2025 结构设计订单 '!C77 -> 140 | E27: ='2025 结构设计订单 '!D77 -> 400 | F27: ='2025 结构设计订单 '!E77 -> Romania | G27: ='2025 结构设计订单 '!F77 -> 出口 | H27: ='2025 结构设计订单 '!G77 -> 2 | I27: =IF((_xlfn.XLOOKUP($C27,'2025 结构设计订单 '!$B:$B,'2025 结构设计订单 '!H:H))=0," ",_xlfn.XLOOKUP($C27,'2025 结构设计订单 '!$B:$B,'2025 结构设计订单 '!H:H)) -> 郭运波 | J27: =IF((_xlfn.XLOOKUP($C27,'2025 结构设计订单 '!$B:$B,'2025 结构设计订单 '!I:I))=0," ",_xlfn.XLOOKUP($C27,'2025 结构设计订单 '!$B:$B,'2025 结构设计订单 '!I:I)) -> 司林杰 | K27: =IF((_xlfn.XLOOKUP($C27,'2025 结构设计订单 '!$B:$B,'2025 结构设计订单 '!J:J))=0," ",_xlfn.XLOOKUP($C27,'2025 结构设计订单 '!$B:$B,'2025 结构设计订单 '!J:J)) -> 45848 | L27: =IF((_xlfn.XLOOKUP($C27,'2025 结构设计订单 '!$B:$B,'2025 结构设计订单 '!K:K))=0," ",_xlfn.XLOOKUP($C27,'2025 结构设计订单 '!$B:$B,'2025 结构设计订单 '!K:K)) | M27: =IF((_xlfn.XLOOKUP($C27,'2025 结构设计订单 '!$B:$B,'2025 结构设计订单 '!M:M))=0," ",_xlfn.XLOOKUP($C27,'2025 结构设计订单 '!$B:$B,'2025 结构设计订单 '!M:M)) -> 45828 | N27: =IF((_xlfn.XLOOKUP($C27,'2025 结构设计订单 '!$B:$B,'2025 结构设计订单 '!N:N))=0," ",_xlfn.XLOOKUP($C27,'2025 结构设计订单 '!$B:$B,'2025 结构设计订单 '!N:N))
B28: 33 | C28: ='2025 结构设计订单 '!B75 -> 813191-813193 | D28: ='2025 结构设计订单 '!C75 -> 30MVAr | E28: ='2025 结构设计订单 '!D75 -> 230 | F28: ='2025 结构设计订单 '!E75 -> 霞浦B区陆上集控站 | G28: ='2025 结构设计订单 '!F75 -> 国内 | H28: ='2025 结构设计订单 '!G75 -> 2 | I28: =IF((_xlfn.XLOOKUP($C28,'2025 结构设计订单 '!$B:$B,'2025 结构设计订单 '!H:H))=0," ",_xlfn.XLOOKUP($C28,'2025 结构设计订单 '!$B:$B,'2025 结构设计订单 '!H:H)) -> 戚彬 | J28: =IF((_xlfn.XLOOKUP($C28,'2025 结构设计订单 '!$B:$B,'2025 结构设计订单 '!I:I))=0," ",_xlfn.XLOOKUP($C28,'2025 结构设计订单 '!$B:$B,'2025 结构设计订单 '!I:I)) -> 董立乔 | K28: =IF((_xlfn.XLOOKUP($C28,'2025 结构设计订单 '!$B:$B,'2025 结构设计订单 '!J:J))=0," ",_xlfn.XLOOKUP($C28,'2025 结构设计订单 '!$B:$B,'2025 结构设计订单 '!J:J)) -> 45848 | L28: =IF((_xlfn.XLOOKUP($C28,'2025 结构设计订单 '!$B:$B,'2025 结构设计订单 '!K:K))=0," ",_xlfn.XLOOKUP($C28,'2025 结构设计订单 '!$B:$B,'2025 结构设计订单 '!K:K)) | M28: =IF((_xlfn.XLOOKUP($C28,'2025 结构设计订单 '!$B:$B,'2025 结构设计订单 '!M:M))=0," ",_xlfn.XLOOKUP($C28,'2025 结构设计订单 '!$B:$B,'2025 结构设计订单 '!M:M)) -> 45848 | N28: =IF((_xlfn.XLOOKUP($C28,'2025 结构设计订单 '!$B:$B,'2025 结构设计订单 '!N:N))=0," ",_xlfn.XLOOKUP($C28,'2025 结构设计订单 '!$B:$B,'2025 结构设计订单 '!N:N))
B29: 34 | C29: ='2025 结构设计订单 '!B76 -> 813111~813113 | D29: ='2025 结构设计订单 '!C76 -> 280 | E29: ='2025 结构设计订单 '!D76 -> 400 | F29: ='2025 结构设计订单 '!E76 -> UK_Statera Energy Framework | G29: ='2025 结构设计订单 '!F76 -> 出口 | H29: ='2025 结构设计订单 '!G76 -> 3 | I29: =IF((_xlfn.XLOOKUP($C29,'2025 结构设计订单 '!$B:$B,'2025 结构设计订单 '!H:H))=0," ",_xlfn.XLOOKUP($C29,'2025 结构设计订单 '!$B:$B,'2025 结构设计订单 '!H:H)) -> 李咏梅 | J29: =IF((_xlfn.XLOOKUP($C29,'2025 结构设计订单 '!$B:$B,'2025 结构设计订单 '!I:I))=0," ",_xlfn.XLOOKUP($C29,'2025 结构设计订单 '!$B:$B,'2025 结构设计订单 '!I:I)) -> 王芳 | K29: =IF((_xlfn.XLOOKUP($C29,'2025 结构设计订单 '!$B:$B,'2025 结构设计订单 '!J:J))=0," ",_xlfn.XLOOKUP($C29,'2025 结构设计订单 '!$B:$B,'2025 结构设计订单 '!J:J)) -> 45848 | L29: =IF((_xlfn.XLOOKUP($C29,'2025 结构设计订单 '!$B:$B,'2025 结构设计订单 '!K:K))=0," ",_xlfn.XLOOKUP($C29,'2025 结构设计订单 '!$B:$B,'2025 结构设计订单 '!K:K)) | M29: =IF((_xlfn.XLOOKUP($C29,'2025 结构设计订单 '!$B:$B,'2025 结构设计订单 '!M:M))=0," ",_xlfn.XLOOKUP($C29,'2025 结构设计订单 '!$B:$B,'2025 结构设计订单 '!M:M)) -> 45849 | N29: =IF((_xlfn.XLOOKUP($C29,'2025 结构设计订单 '!$B:$B,'2025 结构设计订单 '!N:N))=0," ",_xlfn.XLOOKUP($C29,'2025 结构设计订单 '!$B:$B,'2025 结构设计订单 '!N:N))
B30: 35 | C30: ='2025 结构设计订单 '!B77 -> 813072-813073 | D30: ='2025 结构设计订单 '!C77 -> 140 | E30: ='2025 结构设计订单 '!D77 -> 400 | F30: ='2025 结构设计订单 '!E77 -> Romania | G30: ='2025 结构设计订单 '!F77 -> 出口 | H30: ='2025 结构设计订单 '!G77 -> 2 | I30: =IF((_xlfn.XLOOKUP($C30,'2025 结构设计订单 '!$B:$B,'2025 结构设计订单 '!H:H))=0," ",_xlfn.XLOOKUP($C30,'2025 结构设计订单 '!$B:$B,'2025 结构设计订单 '!H:H)) -> 郭运波 | J30: =IF((_xlfn.XLOOKUP($C30,'2025 结构设计订单 '!$B:$B,'2025 结构设计订单 '!I:I))=0," ",_xlfn.XLOOKUP($C30,'2025 结构设计订单 '!$B:$B,'2025 结构设计订单 '!I:I)) -> 司林杰 | K30: =IF((_xlfn.XLOOKUP($C30,'2025 结构设计订单 '!$B:$B,'2025 结构设计订单 '!J:J))=0," ",_xlfn.XLOOKUP($C30,'2025 结构设计订单 '!$B:$B,'2025 结构设计订单 '!J:J)) -> 45848 | L30: =IF((_xlfn.XLOOKUP($C30,'2025 结构设计订单 '!$B:$B,'2025 结构设计订单 '!K:K))=0," ",_xlfn.XLOOKUP($C30,'2025 结构设计订单 '!$B:$B,'2025 结构设计订单 '!K:K)) | M30: =IF((_xlfn.XLOOKUP($C30,'2025 结构设计订单 '!$B:$B,'2025 结构设计订单 '!M:M))=0," ",_xlfn.XLOOKUP($C30,'2025 结构设计订单 '!$B:$B,'2025 结构设计订单 '!M:M)) -> 45828 | N30: =IF((_xlfn.XLOOKUP($C30,'2025 结构设计订单 '!$B:$B,'2025 结构设计订单 '!N:N))=0," ",_xlfn.XLOOKUP($C30,'2025 结构设计订单 '!$B:$B,'2025 结构设计订单 '!N:N))
B31: 26 | C31: ='2025 结构设计订单 '!B78 -> 813168-813169 | D31: ='2025 结构设计订单 '!C78 -> 100 | E31: ='2025 结构设计订单 '!D78 -> 400 | F31: ='2025 结构设计订单 '!E78 -> Romania_Terpezita | G31: ='2025 结构设计订单 '!F78 -> 出口 | H31: ='2025 结构设计订单 '!G78 -> 2 | I31: =IF((_xlfn.XLOOKUP($C31,'2025 结构设计订单 '!$B:$B,'2025 结构设计订单 '!H:H))=0," ",_xlfn.XLOOKUP($C31,'2025 结构设计订单 '!$B:$B,'2025 结构设计订单 '!H:H)) -> 戚彬 | J31: =IF((_xlfn.XLOOKUP($C31,'2025 结构设计订单 '!$B:$B,'2025 结构设计订单 '!I:I))=0," ",_xlfn.XLOOKUP($C31,'2025 结构设计订单 '!$B:$B,'2025 结构设计订单 '!I:I)) -> 王芳 | K31: =IF((_xlfn.XLOOKUP($C31,'2025 结构设计订单 '!$B:$B,'2025 结构设计订单 '!J:J))=0," ",_xlfn.XLOOKUP($C31,'2025 结构设计订单 '!$B:$B,'2025 结构设计订单 '!J:J)) -> 45853 | L31: =IF((_xlfn.XLOOKUP($C31,'2025 结构设计订单 '!$B:$B,'2025 结构设计订单 '!K:K))=0," ",_xlfn.XLOOKUP($C31,'2025 结构设计订单 '!$B:$B,'2025 结构设计订单 '!K:K)) | M31: =IF((_xlfn.XLOOKUP($C31,'2025 结构设计订单 '!$B:$B,'2025 结构设计订单 '!M:M))=0," ",_xlfn.XLOOKUP($C31,'2025 结构设计订单 '!$B:$B,'2025 结构设计订单 '!M:M)) | N31: =IF((_xlfn.XLOOKUP($C31,'2025 结构设计订单 '!$B:$B,'2025 结构设计订单 '!N:N))=0," ",_xlfn.XLOOKUP($C31,'2025 结构设计订单 '!$B:$B,'2025 结构设计订单 '!N:N))
B32: 36 | C32: ='2025 结构设计订单 '!B78 -> 813168-813169 | D32: ='2025 结构设计订单 '!C78 -> 100 | E32: ='2025 结构设计订单 '!D78 -> 400 | F32: ='2025 结构设计订单 '!E78 -> Romania_Terpezita | G32: ='2025 结构设计订单 '!F78 -> 出口 | H32: ='2025 结构设计订单 '!G78 -> 2 | I32: =IF((_xlfn.XLOOKUP($C32,'2025 结构设计订单 '!$B:$B,'2025 结构设计订单 '!H:H))=0," ",_xlfn.XLOOKUP($C32,'2025 结构设计订单 '!$B:$B,'2025 结构设计订单 '!H:H)) -> 戚彬 | J32: =IF((_xlfn.XLOOKUP($C32,'2025 结构设计订单 '!$B:$B,'2025 结构设计订单 '!I:I))=0," ",_xlfn.XLOOKUP($C32,'2025 结构设计订单 '!$B:$B,'2025 结构设计订单 '!I:I)) -> 王芳 | K32: =IF((_xlfn.XLOOKUP($C32,'2025 结构设计订单 '!$B:$B,'2025 结构设计订单 '!J:J))=0," ",_xlfn.XLOOKUP($C32,'2025 结构设计订单 '!$B:$B,'2025 结构设计订单 '!J:J)) -> 45853 | L32: =IF((_xlfn.XLOOKUP($C32,'2025 结构设计订单 '!$B:$B,'2025 结构设计订单 '!K:K))=0," ",_xlfn.XLOOKUP($C32,'2025 结构设计订单 '!$B:$B,'2025 结构设计订单 '!K:K)) | M32: =IF((_xlfn.XLOOKUP($C32,'2025 结构设计订单 '!$B:$B,'2025 结构设计订单 '!M:M))=0," ",_xlfn.XLOOKUP($C32,'2025 结构设计订单 '!$B:$B,'2025 结构设计订单 '!M:M)) | N32: =IF((_xlfn.XLOOKUP($C32,'2025 结构设计订单 '!$B:$B,'2025 结构设计订单 '!N:N))=0," ",_xlfn.XLOOKUP($C32,'2025 结构设计订单 '!$B:$B,'2025 结构设计订单 '!N:N))
B33: 29 | C33: ='2025 结构设计订单 '!B79 -> 813137 | D33: ='2025 结构设计订单 '!C79 -> 80 | E33: ='2025 结构设计订单 '!D79 -> 230 | F33: ='2025 结构设计订单 '!E79 -> 沙特Aramco Asia备用变项目 | G33: ='2025 结构设计订单 '!F79 -> 出口 | H33: ='2025 结构设计订单 '!G79 -> 1 | I33: =IF((_xlfn.XLOOKUP($C33,'2025 结构设计订单 '!$B:$B,'2025 结构设计订单 '!H:H))=0," ",_xlfn.XLOOKUP($C33,'2025 结构设计订单 '!$B:$B,'2025 结构设计订单 '!H:H)) -> 张金环 | J33: =IF((_xlfn.XLOOKUP($C33,'2025 结构设计订单 '!$B:$B,'2025 结构设计订单 '!I:I))=0," ",_xlfn.XLOOKUP($C33,'2025 结构设计订单 '!$B:$B,'2025 结构设计订单 '!I:I)) -> 司林杰 | K33: =IF((_xlfn.XLOOKUP($C33,'2025 结构设计订单 '!$B:$B,'2025 结构设计订单 '!J:J))=0," ",_xlfn.XLOOKUP($C33,'2025 结构设计订单 '!$B:$B,'2025 结构设计订单 '!J:J)) -> 45870 | L33: =IF((_xlfn.XLOOKUP($C33,'2025 结构设计订单 '!$B:$B,'2025 结构设计订单 '!K:K))=0," ",_xlfn.XLOOKUP($C33,'2025 结构设计订单 '!$B:$B,'2025 结构设计订单 '!K:K)) | M33: =IF((_xlfn.XLOOKUP($C33,'2025 结构设计订单 '!$B:$B,'2025 结构设计订单 '!M:M))=0," ",_xlfn.XLOOKUP($C33,'2025 结构设计订单 '!$B:$B,'2025 结构设计订单 '!M:M)) -> 45879 | N33: =IF((_xlfn.XLOOKUP($C33,'2025 结构设计订单 '!$B:$B,'2025 结构设计订单 '!N:N))=0," ",_xlfn.XLOOKUP($C33,'2025 结构设计订单 '!$B:$B,'2025 结构设计订单 '!N:N))
B34: 37 | C34: ='2025 结构设计订单 '!B79 -> 813137 | D34: ='2025 结构设计订单 '!C79 -> 80 | E34: ='2025 结构设计订单 '!D79 -> 230 | F34: ='2025 结构设计订单 '!E79 -> 沙特Aramco Asia备用变项目 | G34: ='2025 结构设计订单 '!F79 -> 出口 | H34: ='2025 结构设计订单 '!G79 -> 1 | I34: =IF((_xlfn.XLOOKUP($C34,'2025 结构设计订单 '!$B:$B,'2025 结构设计订单 '!H:H))=0," ",_xlfn.XLOOKUP($C34,'2025 结构设计订单 '!$B:$B,'2025 结构设计订单 '!H:H)) -> 张金环 | J34: =IF((_xlfn.XLOOKUP($C34,'2025 结构设计订单 '!$B:$B,'2025 结构设计订单 '!I:I))=0," ",_xlfn.XLOOKUP($C34,'2025 结构设计订单 '!$B:$B,'2025 结构设计订单 '!I:I)) -> 司林杰 | K34: =IF((_xlfn.XLOOKUP($C34,'2025 结构设计订单 '!$B:$B,'2025 结构设计订单 '!J:J))=0," ",_xlfn.XLOOKUP($C34,'2025 结构设计订单 '!$B:$B,'2025 结构设计订单 '!J:J)) -> 45870 | L34: =IF((_xlfn.XLOOKUP($C34,'2025 结构设计订单 '!$B:$B,'2025 结构设计订单 '!K:K))=0," ",_xlfn.XLOOKUP($C34,'2025 结构设计订单 '!$B:$B,'2025 结构设计订单 '!K:K)) | M34: =IF((_xlfn.XLOOKUP($C34,'2025 结构设计订单 '!$B:$B,'2025 结构设计订单 '!M:M))=0," ",_xlfn.XLOOKUP($C34,'2025 结构设计订单 '!$B:$B,'2025 结构设计订单 '!M:M)) -> 45879 | N34: =IF((_xlfn.XLOOKUP($C34,'2025 结构设计订单 '!$B:$B,'2025 结构设计订单 '!N:N))=0," ",_xlfn.XLOOKUP($C34,'2025 结构设计订单 '!$B:$B,'2025 结构设计订单 '!N:N))
B35: 5 | C35: ='2025 结构设计订单 '!B80 -> 850623 | D35: ='2025 结构设计订单 '!C80 -> 120 | E35: ='2025 结构设计订单 '!D80 -> 220 | F35: ='2025 结构设计订单 '!E80 -> 山西运城临晋3号主变返厂大修 | G35: ='2025 结构设计订单 '!F80 -> 国内 | H35: ='2025 结构设计订单 '!G80 -> 1 | I35: =IF((_xlfn.XLOOKUP($C35,'2025 结构设计订单 '!$B:$B,'2025 结构设计订单 '!H:H))=0," ",_xlfn.XLOOKUP($C35,'2025 结构设计订单 '!$B:$B,'2025 结构设计订单 '!H:H)) -> 郑瑞阳 | J35: =IF((_xlfn.XLOOKUP($C35,'2025 结构设计订单 '!$B:$B,'2025 结构设计订单 '!I:I))=0," ",_xlfn.XLOOKUP($C35,'2025 结构设计订单 '!$B:$B,'2025 结构设计订单 '!I:I)) -> 董立乔 | K35: =IF((_xlfn.XLOOKUP($C35,'2025 结构设计订单 '!$B:$B,'2025 结构设计订单 '!J:J))=0," ",_xlfn.XLOOKUP($C35,'2025 结构设计订单 '!$B:$B,'2025 结构设计订单 '!J:J)) -> 45874 | L35: =IF((_xlfn.XLOOKUP($C35,'2025 结构设计订单 '!$B:$B,'2025 结构设计订单 '!K:K))=0," ",_xlfn.XLOOKUP($C35,'2025 结构设计订单 '!$B:$B,'2025 结构设计订单 '!K:K)) | M35: =IF((_xlfn.XLOOKUP($C35,'2025 结构设计订单 '!$B:$B,'2025 结构设计订单 '!M:M))=0," ",_xlfn.XLOOKUP($C35,'2025 结构设计订单 '!$B:$B,'2025 结构设计订单 '!M:M)) | N35: =IF((_xlfn.XLOOKUP($C35,'2025 结构设计订单 '!$B:$B,'2025 结构设计订单 '!N:N))=0," ",_xlfn.XLOOKUP($C35,'2025 结构设计订单 '!$B:$B,'2025 结构设计订单 '!N:N))
B36: 38 | C36: ='2025 结构设计订单 '!B80 -> 850623 | D36: ='2025 结构设计订单 '!C80 -> 120 | E36: ='2025 结构设计订单 '!D80 -> 220 | F36: ='2025 结构设计订单 '!E80 -> 山西运城临晋3号主变返厂大修 | G36: ='2025 结构设计订单 '!F80 -> 国内 | H36: ='2025 结构设计订单 '!G80 -> 1 | I36: =IF((_xlfn.XLOOKUP($C36,'2025 结构设计订单 '!$B:$B,'2025 结构设计订单 '!H:H))=0," ",_xlfn.XLOOKUP($C36,'2025 结构设计订单 '!$B:$B,'2025 结构设计订单 '!H:H)) -> 郑瑞阳 | J36: =IF((_xlfn.XLOOKUP($C36,'2025 结构设计订单 '!$B:$B,'2025 结构设计订单 '!I:I))=0," ",_xlfn.XLOOKUP($C36,'2025 结构设计订单 '!$B:$B,'2025 结构设计订单 '!I:I)) -> 董立乔 | K36: =IF((_xlfn.XLOOKUP($C36,'2025 结构设计订单 '!$B:$B,'2025 结构设计订单 '!J:J))=0," ",_xlfn.XLOOKUP($C36,'2025 结构设计订单 '!$B:$B,'2025 结构设计订单 '!J:J)) -> 45874 | L36: =IF((_xlfn.XLOOKUP($C36,'2025 结构设计订单 '!$B:$B,'2025 结构设计订单 '!K:K))=0," ",_xlfn.XLOOKUP($C36,'2025 结构设计订单 '!$B:$B,'2025 结构设计订单 '!K:K)) | M36: =IF((_xlfn.XLOOKUP($C36,'2025 结构设计订单 '!$B:$B,'2025 结构设计订单 '!M:M))=0," ",_xlfn.XLOOKUP($C36,'2025 结构设计订单 '!$B:$B,'2025 结构设计订单 '!M:M)) | N36: =IF((_xlfn.XLOOKUP($C36,'2025 结构设计订单 '!$B:$B,'2025 结构设计订单 '!N:N))=0," ",_xlfn.XLOOKUP($C36,'2025 结构设计订单 '!$B:$B,'2025 结构设计订单 '!N:N))
B37: 6 | C37: ='2025 结构设计订单 '!B81 -> 813025-8123027 | D37: ='2025 结构设计订单 '!C81 -> 330 | E37: ='2025 结构设计订单 '!D81 -> 330 | F37: ='2025 结构设计订单 '!E81 -> Nigeria Brownfield | G37: ='2025 结构设计订单 '!F81 -> 出口 | H37: ='2025 结构设计订单 '!G81 -> 2 3 | I37: =IF((_xlfn.XLOOKUP($C37,'2025 结构设计订单 '!$B:$B,'2025 结构设计订单 '!H:H))=0," ",_xlfn.XLOOKUP($C37,'2025 结构设计订单 '!$B:$B,'2025 结构设计订单 '!H:H)) -> 李咏梅 | J37: =IF((_xlfn.XLOOKUP($C37,'2025 结构设计订单 '!$B:$B,'2025 结构设计订单 '!I:I))=0," ",_xlfn.XLOOKUP($C37,'2025 结构设计订单 '!$B:$B,'2025 结构设计订单 '!I:I)) -> 司林杰 | K37: =IF((_xlfn.XLOOKUP($C37,'2025 结构设计订单 '!$B:$B,'2025 结构设计订单 '!J:J))=0," ",_xlfn.XLOOKUP($C37,'2025 结构设计订单 '!$B:$B,'2025 结构设计订单 '!J:J)) -> 45879 | L37: =IF((_xlfn.XLOOKUP($C37,'2025 结构设计订单 '!$B:$B,'2025 结构设计订单 '!K:K))=0," ",_xlfn.XLOOKUP($C37,'2025 结构设计订单 '!$B:$B,'2025 结构设计订单 '!K:K)) | M37: =IF((_xlfn.XLOOKUP($C37,'2025 结构设计订单 '!$B:$B,'2025 结构设计订单 '!M:M))=0," ",_xlfn.XLOOKUP($C37,'2025 结构设计订单 '!$B:$B,'2025 结构设计订单 '!M:M)) -> 45879 | N37: =IF((_xlfn.XLOOKUP($C37,'2025 结构设计订单 '!$B:$B,'2025 结构设计订单 '!N:N))=0," ",_xlfn.XLOOKUP($C37,'2025 结构设计订单 '!$B:$B,'2025 结构设计订单 '!N:N))
